Workbook

Sheet Légende
A1: MODE D'EMPLOI ET LÉGENDE
A2: Catalogue des services — priorités, couverture de supervision et rapprochement Kapptivate
A4: Version | B4: v3.0 — conforme aux caractéristiques Kapptivate (fusion 3G/4G, MaxIt = canal, priorités P1 par défaut)
A5: Date de mise à jour | B5: À compléter
A6: Responsable du document | B6: À compléter
A7: Périmètre | B7: 256 services répartis en 19 domaines
A9: 1. Niveaux de priorité
A10: Niveau | B10: Libellé | C10: Définition (à valider par l'équipe)
A11: P1 | B11: Critique | C11: Service à revenu direct ou à fort impact client. Supervision obligatoire.
A12: P2 | B12: Important | C12: Impact client réel mais contournable. Supervision fortement recommandée.
A13: P3 | B13: Secondaire | C13: Service de confort ou à faible volume. Supervision au mieux.
A15: 2. Règles de conformité appliquées à cette version (fournies par l'utilisateur)
A16: • | B16: Une sonde « 3G | X » et « 4G | X » désignent le même service testé sur deux technologies : elles sont fusionnées en une seule ligne du catalogue, avec la ou les technologies notées en observation.
A17: • | B17: MaxIt n'est pas une famille de services à part entière : c'est un canal web alternatif donnant accès à des services déjà catalogués ailleurs. Les entrées « Maxit-… » ne créent donc aucune nouvelle ligne dans le catalogue — elles sont recensées à part dans l'onglet « MaxIt (canal alternatif) », avec leur correspondance probable.
A18: • | B18: Pour les services Orange Money (Core, add-on Local, add-on Group, Bank to Wallet), SVA USSD, SVA SMS et PICO : si aucune priorité n'était fournie, elle est définie par défaut à P1 (à ajuster si besoin).
A20: 3. Nouveaux domaines issus de l'export Kapptivate
A21: Domaine | B21: Catégorie(s) Kapptivate d'origine
A22: OM Bank to Wallet | B22: OM Bank to Wallet
A23: Data Mobile (sondes réseau 3G/4G) | B23: Data 3G / Data 4G / Data Social Network (sondes fusionnées)
A24: Supervision Externe (Downdetector) | B24: Downdetector
A25: Nimba Plus | B25: Nimba Plus
A26: PICO | B26: PICO
A27: Outils SI internes | B27: OUTILS SI
A28: Audit Facturation (Voix) | B28: Audit Facturation
A29: Supervision plateforme (Divers) | B29: ZZ_Management
A30: SVA Data | B30: SVA Data (contenu — Playweez, Playciné, YouScribe, etc.)
A31: Voix Numéro Court | B31: VOIX NUMERO COURT
A32: SVA USSD | B32: SVA USSD (+ services « Autres SVA » reclassés, voir onglet Reclassement SVA)
A33: SVA SMS | B33: SVA SMS (+ services « Autres SVA » reclassés, voir onglet Reclassement SVA)
A34: MaxIt volontairement absent de cette liste : ce n'est pas un domaine de services (voir §2).
A35: 4. Méthode de rapprochement Kapptivate ↔ Catalogue
A36: • | B36: Chaque service Kapptivate est comparé à tous les services du catalogue par similarité textuelle.
A37: • | B37: Score ≥ 90% → « Déjà dans le catalogue ». Score 60-89% → « À vérifier » (arbitrage humain requis). Score < 60% → « Nouveau », ajouté au catalogue avec Supervisé = Oui / Outil = Kapptivate.
A38: • | B38: Ce score est une approximation automatique — la tranche « À vérifier » doit être tranchée par l'équipe.
A40: 5. Colonnes de l'onglet Catalogue
A41: Colonne | B41: Format attendu | C41: Contenu
A42: Domaine | B42: Liste déroulante | C42: Famille de services.
A43: Service | B43: Texte | C43: Libellé exact du service.
A44: Priorité | B44: Liste déroulante P1/P2/P3 | C44: Criticité métier.
A45: Supervisé | B45: Liste déroulante Oui/Non | C45: Existe-t-il une sonde active aujourd'hui ?
...

Sheet Synthèse
A1: SYNTHÈSE — COUVERTURE DE SUPERVISION
A2: Onglet entièrement calculé (formules) à partir de l'onglet Catalogue. Se met à jour automatiquement.
A4: Services P1 NON supervisés | B4: =COUNTIFS(Catalogue!$C$5:$C$450,"P1",Catalogue!$D$5:$D$450,"Non") -> 6 | C4: ← Priorité d'action n°1.
A5: Taux de couverture global | B5: =IFERROR(COUNTIF(Catalogue!$D$5:$D$450,"Oui")/COUNTA(Catalogue!$B$5:$B$450),"-") -> 0.8984375 | C5: ← Part des services dotés d'une sonde active (catalogue complet).
A6: Dont priorité restant à définir | B6: =COUNTIFS(Catalogue!$B$5:$B$450,"<>",Catalogue!$C$5:$C$450,"") -> 75 | C6: ← Domaines hors OM/SVA USSD/SVA SMS/PICO (pas de règle de priorité par défaut).
A8: 1. Couverture par domaine
A9: Domaine | B9: Nb services | C9: P1 | D9: P2 | E9: P3 | F9: Non priorisé | G9: Supervisés | H9: Non supervisés | I9: Taux de couverture | J9: Dont P1 non supervisés
A10: Voix | B10: =COUNTIF(Catalogue!$A$5:$A$450,$A10) -> 20 | C10: =COUNTIFS(Catalogue!$A$5:$A$450,$A10,Catalogue!$C$5:$C$450,"P1") -> 2 | D10: =COUNTIFS(Catalogue!$A$5:$A$450,$A10,Catalogue!$C$5:$C$450,"P2") -> 2 | E10: =COUNTIFS(Catalogue!$A$5:$A$450,$A10,Catalogue!$C$5:$C$450,"P3") -> 3 | F10: =$B10-SUM($C10:$E10) -> 13 | G10: =COUNTIFS(Catalogue!$A$5:$A$450,$A10,Catalogue!$D$5:$D$450,"Oui") -> 17 | H10: =COUNTIFS(Catalogue!$A$5:$A$450,$A10,Catalogue!$D$5:$D$450,"Non") -> 3 | I10: =IFERROR($G10/$B10,"-") -> 0.85 | J10: =COUNTIFS(Catalogue!$A$5:$A$450,$A10,Catalogue!$C$5:$C$450,"P1",Catalogue!$D$5:$D$450,"Non") -> 1
A11: Orange Money Core | B11: =COUNTIF(Catalogue!$A$5:$A$450,$A11) -> 24 | C11: =COUNTIFS(Catalogue!$A$5:$A$450,$A11,Catalogue!$C$5:$C$450,"P1") -> 14 | D11: =COUNTIFS(Catalogue!$A$5:$A$450,$A11,Catalogue!$C$5:$C$450,"P2") -> 9 | E11: =COUNTIFS(Catalogue!$A$5:$A$450,$A11,Catalogue!$C$5:$C$450,"P3") -> 1 | F11: =$B11-SUM($C11:$E11) -> 0 | G11: =COUNTIFS(Catalogue!$A$5:$A$450,$A11,Catalogue!$D$5:$D$450,"Oui") -> 24 | H11: =COUNTIFS(Catalogue!$A$5:$A$450,$A11,Catalogue!$D$5:$D$450,"Non") -> 0 | I11: =IFERROR($G11/$B11,"-") -> 1 | J11: =COUNTIFS(Catalogue!$A$5:$A$450,$A11,Catalogue!$C$5:$C$450,"P1",Catalogue!$D$5:$D$450,"Non") -> 0
A12: Orange Money add-on Local | B12: =COUNTIF(Catalogue!$A$5:$A$450,$A12) -> 42 | C12: =COUNTIFS(Catalogue!$A$5:$A$450,$A12,Catalogue!$C$5:$C$450,"P1") -> 22 | D12: =COUNTIFS(Catalogue!$A$5:$A$450,$A12,Catalogue!$C$5:$C$450,"P2") -> 16 | E12: =COUNTIFS(Catalogue!$A$5:$A$450,$A12,Catalogue!$C$5:$C$450,"P3") -> 4 | F12: =$B12-SUM($C12:$E12) -> 0 | G12: =COUNTIFS(Catalogue!$A$5:$A$450,$A12,Catalogue!$D$5:$D$450,"Oui") -> 37 | H12: =COUNTIFS(Catalogue!$A$5:$A$450,$A12,Catalogue!$D$5:$D$450,"Non") -> 5 | I12: =IFERROR($G12/$B12,"-") -> 0.88095238 | J12: =COUNTIFS(Catalogue!$A$5:$A$450,$A12,Catalogue!$C$5:$C$450,"P1",Catalogue!$D$5:$D$450,"Non") -> 0
A13: Orange Money add-on Group | B13: =COUNTIF(Catalogue!$A$5:$A$450,$A13) -> 23 | C13: =COUNTIFS(Catalogue!$A$5:$A$450,$A13,Catalogue!$C$5:$C$450,"P1") -> 19 | D13: =COUNTIFS(Catalogue!$A$5:$A$450,$A13,Catalogue!$C$5:$C$450,"P2") -> 4 | E13: =COUNTIFS(Catalogue!$A$5:$A$450,$A13,Catalogue!$C$5:$C$450,"P3") -> 0 | F13: =$B13-SUM($C13:$E13) -> 0 | G13: =COUNTIFS(Catalogue!$A$5:$A$450,$A13,Catalogue!$D$5:$D$450,"Oui") -> 16 | H13: =COUNTIFS(Catalogue!$A$5:$A$450,$A13,Catalogue!$D$5:$D$450,"Non") -> 7 | I13: =IFERROR($G13/$B13,"-") -> 0.69565217 | J13: =COUNTIFS(Catalogue!$A$5:$A$450,$A13,Catalogue!$C$5:$C$450,"P1",Catalogue!$D$5:$D$450,"Non") -> 4
A14: ZEBRA | B14: =COUNTIF(Catalogue!$A$5:$A$450,$A14) -> 5 | C14: =COUNTIFS(Catalogue!$A$5:$A$450,$A14,Catalogue!$C$5:$C$450,"P1") -> 0 | D14: =COUNTIFS(Catalogue!$A$5:$A$450,$A14,Catalogue!$C$5:$C$450,"P2") -> 2 | E14: =COUNTIFS(Catalogue!$A$5:$A$450,$A14,Catalogue!$C$5:$C$450,"P3") -> 2 | F14: =$B14-SUM($C14:$E14) -> 1 | G14: =COUNTIFS(Catalogue!$A$5:$A$450,$A14,Catalogue!$D$5:$D$450,"Oui") -> 3 | H14: =COUNTIFS(Catalogue!$A$5:$A$450,$A14,Catalogue!$D$5:$D$450,"Non") -> 2 | I14: =IFERROR($G14/$B14,"-") -> 0.6 | J14: =COUNTIFS(Catalogue!$A$5:$A$450,$A14,Catalogue!$C$5:$C$450,"P1",Catalogue!$D$5:$D$450,"Non") -> 0
A15: Autres SVA | B15: =COUNTIF(Catalogue!$A$5:$A$450,$A15) -> 12 | C15: =COUNTIFS(Catalogue!$A$5:$A$450,$A15,Catalogue!$C$5:$C$450,"P1") -> 0 | D15: =COUNTIFS(Catalogue!$A$5:$A$450,$A15,Catalogue!$C$5:$C$450,"P2") -> 5 | E15: =COUNTIFS(Catalogue!$A$5:$A$450,$A15,Catalogue!$C$5:$C$450,"P3") -> 7 | F15: =$B15-SUM($C15:$E15) -> 0 | G15: =COUNTIFS(Catalogue!$A$5:$A$450,$A15,Catalogue!$D$5:$D$450,"Oui") -> 7 | H15: =COUNTIFS(Catalogue!$A$5:$A$450,$A15,Catalogue!$D$5:$D$450,"Non") -> 5 | I15: =IFERROR($G15/$B15,"-") -> 0.58333333 | J15: =COUNTIFS(Catalogue!$A$5:$A$450,$A15,Catalogue!$C$5:$C$450,"P1",Catalogue!$D$5:$D$450,"Non") -> 0
A16: Interface web de stimulation | B16: =COUNTIF(Catalogue!$A$5:$A$450,$A16) -> 2 | C16: =COUNTIFS(Catalogue!$A$5:$A$450,$A16,Catalogue!$C$5:$C$450,"P1") -> 1 | D16: =COUNTIFS(Catalogue!$A$5:$A$450,$A16,Catalogue!$C$5:$C$450,"P2") -> 1 | E16: =COUNTIFS(Catalogue!$A$5:$A$450,$A16,Catalogue!$C$5:$C$450,"P3") -> 0 | F16: =$B16-SUM($C16:$E16) -> 0 | G16: =COUNTIFS(Catalogue!$A$5:$A$450,$A16,Catalogue!$D$5:$D$450,"Oui") -> 0 | H16: =COUNTIFS(Catalogue!$A$5:$A$450,$A16,Catalogue!$D$5:$D$450,"Non") -> 2 | I16: =IFERROR($G16/$B16,"-") -> 0 | J16: =COUNTIFS(Catalogue!$A$5:$A$450,$A16,Catalogue!$C$5:$C$450,"P1",Catalogue!$D$5:$D$450,"Non") -> 1
A17: OM Bank to Wallet | B17: =COUNTIF(Catalogue!$A$5:$A$450,$A17) -> 23 | C17: =COUNTIFS(Catalogue!$A$5:$A$450,$A17,Catalogue!$C$5:$C$450,"P1") -> 23 | D17: =COUNTIFS(Catalogue!$A$5:$A$450,$A17,Catalogue!$C$5:$C$450,"P2") -> 0 | E17: =COUNTIFS(Catalogue!$A$5:$A$450,$A17,Catalogue!$C$5:$C$450,"P3") -> 0 | F17: =$B17-SUM($C17:$E17) -> 0 | G17: =COUNTIFS(Catalogue!$A$5:$A$450,$A17,Catalogue!$D$5:$D$450,"Oui") -> 23 | H17: =COUNTIFS(Catalogue!$A$5:$A$450,$A17,Catalogue!$D$5:$D$450,"Non") -> 0 | I17: =IFERROR($G17/$B17,"-") -> 1 | J17: =COUNTIFS(Catalogue!$A$5:$A$450,$A17,Catalogue!$C$5:$C$450,"P1",Catalogue!$D$5:$D$450,"Non") -> 0
A18: Data Mobile (sondes réseau 3G/4G) | B18: =COUNTIF(Catalogue!$A$5:$A$450,$A18) -> 16 | C18: =COUNTIFS(Catalogue!$A$5:$A$450,$A18,Catalogue!$C$5:$C$450,"P1") -> 0 | D18: =COUNTIFS(Catalogue!$A$5:$A$450,$A18,Catalogue!$C$5:$C$450,"P2") -> 0 | E18: =COUNTIFS(Catalogue!$A$5:$A$450,$A18,Catalogue!$C$5:$C$450,"P3") -> 0 | F18: =$B18-SUM($C18:$E18) -> 16 | G18: =COUNTIFS(Catalogue!$A$5:$A$450,$A18,Catalogue!$D$5:$D$450,"Oui") -> 16 | H18: =COUNTIFS(Catalogue!$A$5:$A$450,$A18,Catalogue!$D$5:$D$450,"Non") -> 0 | I18: =IFERROR($G18/$B18,"-") -> 1 | J18: =COUNTIFS(Catalogue!$A$5:$A$450,$A18,Catalogue!$C$5:$C$450,"P1",Catalogue!$D$5:$D$450,"Non") -> 0
A19: Supervision Externe (Downdetector) | B19: =COUNTIF(Catalogue!$A$5:$A$450,$A19) -> 7 | C19: =COUNTIFS(Catalogue!$A$5:$A$450,$A19,Catalogue!$C$5:$C$450,"P1") -> 0 | D19: =COUNTIFS(Catalogue!$A$5:$A$450,$A19,Catalogue!$C$5:$C$450,"P2") -> 0 | E19: =COUNTIFS(Catalogue!$A$5:$A$450,$A19,Catalogue!$C$5:$C$450,"P3") -> 0 | F19: =$B19-SUM($C19:$E19) -> 7 | G19: =COUNTIFS(Catalogue!$A$5:$A$450,$A19,Catalogue!$D$5:$D$450,"Oui") -> 7 | H19: =COUNTIFS(Catalogue!$A$5:$A$450,$A19,Catalogue!$D$5:$D$450,"Non") -> 0 | I19: =IFERROR($G19/$B19,"-") -> 1 | J19: =COUNTIFS(Catalogue!$A$5:$A$450,$A19,Catalogue!$C$5:$C$450,"P1",Catalogue!$D$5:$D$450,"Non") -> 0
A20: Nimba Plus | B20: =COUNTIF(Catalogue!$A$5:$A$450,$A20) -> 10 | C20: =COUNTIFS(Catalogue!$A$5:$A$450,$A20,Catalogue!$C$5:$C$450,"P1") -> 0 | D20: =COUNTIFS(Catalogue!$A$5:$A$450,$A20,Catalogue!$C$5:$C$450,"P2") -> 0 | E20: =COUNTIFS(Catalogue!$A$5:$A$450,$A20,Catalogue!$C$5:$C$450,"P3") -> 0 | F20: =$B20-SUM($C20:$E20) -> 10 | G20: =COUNTIFS(Catalogue!$A$5:$A$450,$A20,Catalogue!$D$5:$D$450,"Oui") -> 10 | H20: =COUNTIFS(Catalogue!$A$5:$A$450,$A20,Catalogue!$D$5:$D$450,"Non") -> 0 | I20: =IFERROR($G20/$B20,"-") -> 1 | J20: =COUNTIFS(Catalogue!$A$5:$A$450,$A20,Catalogue!$C$5:$C$450,"P1",Catalogue!$D$5:$D$450,"Non") -> 0
A21: PICO | B21: =COUNTIF(Catalogue!$A$5:$A$450,$A21) -> 7 | C21: =COUNTIFS(Catalogue!$A$5:$A$450,$A21,Catalogue!$C$5:$C$450,"P1") -> 7 | D21: =COUNTIFS(Catalogue!$A$5:$A$450,$A21,Catalogue!$C$5:$C$450,"P2") -> 0 | E21: =COUNTIFS(Catalogue!$A$5:$A$450,$A21,Catalogue!$C$5:$C$450,"P3") -> 0 | F21: =$B21-SUM($C21:$E21) -> 0 | G21: =COUNTIFS(Catalogue!$A$5:$A$450,$A21,Catalogue!$D$5:$D$450,"Oui") -> 7 | H21: =COUNTIFS(Catalogue!$A$5:$A$450,$A21,Catalogue!$D$5:$D$450,"Non") -> 0 | I21: =IFERROR($G21/$B21,"-") -> 1 | J21: =COUNTIFS(Catalogue!$A$5:$A$450,$A21,Catalogue!$C$5:$C$450,"P1",Catalogue!$D$5:$D$450,"Non") -> 0
... A28: SVA SMS | B28: =COUNTIF(Catalogue!$A$5:$A$450,$A28) -> 5 | C28: =COUNTIFS(Catalogue!$A$5:$A$450,$A28,Catalogue!$C$5:$C$450,"P1") -> 3 | D28: =COUNTIFS(Catalogue!$A$5:$A$450,$A28,Catalogue!$C$5:$C$450,"P2") -> 1 | E28: =COUNTIFS(Catalogue!$A$5:$A$450,$A28,Catalogue!$C$5:$C$450,"P3") -> 1 | F28: =$B28-SUM($C28:$E28) -> 0 | G28: =COUNTIFS(Catalogue!$A$5:$A$450,$A28,Catalogue!$D$5:$D$450,"Oui") -> 4 | H28: =COUNTIFS(Catalogue!$A$5:$A$450,$A28,Catalogue!$D$5:$D$450,"Non") -> 1 | I28: =IFERROR($G28/$B28,"-") -> 0.8 | J28: =COUNTIFS(Catalogue!$A$5:$A$450,$A28,Catalogue!$C$5:$C$450,"P1",Catalogue!$D$5:$D$450,"Non") -> 0
A29: TOTAL | B29: =SUM(B10:B28) -> 256 | C29: =SUM(C10:C28) -> 102 | D29: =SUM(D10:D28) -> 46 | E29: =SUM(E10:E28) -> 33 | F29: =SUM(F10:F28) -> 75 | G29: =SUM(G10:G28) -> 230 | H29: =SUM(H10:H28) -> 26 | I29: =IFERROR($G29/$B29,"-") -> 0.8984375 | J29: =SUM(J10:J28) -> 6
A31: 2. Couverture par niveau de priorité
A32: Priorité | B32: Nb services | C32: Supervisés | D32: Non supervisés | E32: Taux de couverture
A33: P1 | B33: =COUNTIF(Catalogue!$C$5:$C$450,$A33) -> 102 | C33: =COUNTIFS(Catalogue!$C$5:$C$450,$A33,Catalogue!$D$5:$D$450,"Oui") -> 96 | D33: =COUNTIFS(Catalogue!$C$5:$C$450,$A33,Catalogue!$D$5:$D$450,"Non") -> 6 | E33: =IFERROR($C33/$B33,"-") -> 0.94117647
A34: P2 | B34: =COUNTIF(Catalogue!$C$5:$C$450,$A34) -> 46 | C34: =COUNTIFS(Catalogue!$C$5:$C$450,$A34,Catalogue!$D$5:$D$450,"Oui") -> 34 | D34: =COUNTIFS(Catalogue!$C$5:$C$450,$A34,Catalogue!$D$5:$D$450,"Non") -> 12 | E34: =IFERROR($C34/$B34,"-") -> 0.73913043
A35: P3 | B35: =COUNTIF(Catalogue!$C$5:$C$450,$A35) -> 33 | C35: =COUNTIFS(Catalogue!$C$5:$C$450,$A35,Catalogue!$D$5:$D$450,"Oui") -> 26 | D35: =COUNTIFS(Catalogue!$C$5:$C$450,$A35,Catalogue!$D$5:$D$450,"Non") -> 7 | E35: =IFERROR($C35/$B35,"-") -> 0.78787879
A36: Non priorisé | B36: =COUNTA(Catalogue!$B$5:$B$450)-SUM(B33:B35) -> 75 | C36: =COUNTIFS(Catalogue!$C$5:$C$450,"",Catalogue!$D$5:$D$450,"Oui") -> 56 | D36: =COUNTIFS(Catalogue!$C$5:$C$450,"",Catalogue!$D$5:$D$450,"Non") -> 1 | E36: =IFERROR($C36/$B36,"-") -> 0.74666667
A38: 3. Services couverts par outil
A39: Outil | B39: Nb services | C39: Dont P1
A40: Kapptivate | B40: =SUMPRODUCT(--ISNUMBER(SEARCH($A40,Catalogue!$E$5:$E$450))) -> 219 | C40: =SUMPRODUCT(--ISNUMBER(SEARCH($A40,Catalogue!$E$5:$E$450)),--(Catalogue!$C$5:$C$450="P1")) -> 95
A41: Daset | B41: =SUMPRODUCT(--ISNUMBER(SEARCH($A41,Catalogue!$E$5:$E$450))) -> 22 | C41: =SUMPRODUCT(--ISNUMBER(SEARCH($A41,Catalogue!$E$5:$E$450)),--(Catalogue!$C$5:$C$450="P1")) -> 4
A42: Voset | B42: =SUMPRODUCT(--ISNUMBER(SEARCH($A42,Catalogue!$E$5:$E$450))) -> 1 | C42: =SUMPRODUCT(--ISNUMBER(SEARCH($A42,Catalogue!$E$5:$E$450)),--(Catalogue!$C$5:$C$450="P1")) -> 0
A43: Nagios | B43: =SUMPRODUCT(--ISNUMBER(SEARCH($A43,Catalogue!$E$5:$E$450))) -> 2 | C43: =SUMPRODUCT(--ISNUMBER(SEARCH($A43,Catalogue!$E$5:$E$450)),--(Catalogue!$C$5:$C$450="P1")) -> 1
A44: OTARIE | B44: =SUMPRODUCT(--ISNUMBER(SEARCH($A44,Catalogue!$E$5:$E$450))) -> 1 | C44: =SUMPRODUCT(--ISNUMBER(SEARCH($A44,Catalogue!$E$5:$E$450)),--(Catalogue!$C$5:$C$450="P1")) -> 1
A45: ELK | B45: =SUMPRODUCT(--ISNUMBER(SEARCH($A45,Catalogue!$E$5:$E$450))) -> 6 | C45: =SUMPRODUCT(--ISNUMBER(SEARCH($A45,Catalogue!$E$5:$E$450)),--(Catalogue!$C$5:$C$450="P1")) -> 6
A46: Note : un service supervisé par deux outils est compté dans chaque ligne.

Sheet Synthèse Kapptivate
A1: SYNTHÈSE — INTÉGRATION DE L'EXPORT KAPPTIVATE
A2: Indicateurs calculés à partir des onglets Comparatif Kapptivate, MaxIt et Doublons Kapptivate.
A4: Lignes de service dans l'export | B4: 346
A5: Services distincts après fusion 3G/4G | B5: 317
A6: dont sondes techniques fusionnées (3G/4G) | B6: 24
A7: Doublons résiduels dans l'export | B7: 8
A8: MaxIt — canal alternatif (exclu du catalogue) | B8: 34
A9: Déjà dans le catalogue (≥90% de similarité) | B9: 122
A10: À vérifier manuellement (60-89%) | B10: 35
A11: Nouveaux services ajoutés au catalogue (<60%) | B11: 126
A12: dont priorité P1 par défaut (OM/SVA USSD/SVA SMS/PICO) | B12: 53
A13: Taille du catalogue avant / après | B13: 130 → 256
A16: Catégorie Kapptivate | B16: Nb services (après fusion)
A17: OM Bank to Wallet | B17: 53
A18: OM Addons Locaux | B18: 42
A19: SVA USSD | B19: 38
A20: Maxt-it | B20: 34
A21: OM Core | B21: 30
A22: SVA Data | B22: 16
A23: VOIX | B23: 14
A24: Nimba Plus | B24: 12
A25: Data Social Network | B25: 12
A26: Data 4G | B26: 10
A27: OM Addons Group | B27: 10
A28: Audit Facturation | B28: 9
... A36: ZZ_Management | B36: 1
A39: Statut | B39: Nb services
A40: Déjà dans le catalogue | B40: 122
A41: À vérifier | B41: 35
A42: Nouveau — ajouté | B42: 126
A43: MaxIt (canal alternatif) | B43: 34

Sheet Catalogue
A1: CATALOGUE DES SERVICES — PRIORITÉS ET COUVERTURE DE SUPERVISION
A2: Modèle réutilisable. Lignes issues de l'export Kapptivate repérées par « NOUVEAU » (colonne J, fond vert). MaxIt n'apparaît pas ici : voir l'onglet dédié « MaxIt (canal alternatif) ». Cellules jaunes = à compléter.
A4: Domaine | B4: Service | C4: Priorité | D4: Supervisé | E4: Outil(s) de supervision | F4: SIM / MSISDN de test | G4: Sonde / Terminal | H4: Dernière vérification | I4: Observations | J4: Origine
A5: Voix | B5: Postpaid Voix | C5: P2 | D5: Oui | E5: Voset | F5: 628414773 / 628414762 / 628414707 / 628414704 / 623755594 / 623755751 / 623755766 / 623755856 / 623755714 / 0033326867239 | I5: Le numéro 0033326867239 est un numéro international (France) — à confirmer : sonde d'appel entrant ? | J5: Catalogue initial
A6: Voix | B6: Prepaid Voix | C6: P1 | D6: Non | I6: ALERTE : service P1 sans supervision. | J6: Catalogue initial
A7: Voix | B7: Data Mobile | C7: P1 | D7: Oui | E7: OTARIE / Nagios | I7: Supervision réseau (sans SIM de test dédiée). | J7: Catalogue initial
A8: Voix | B8: Data Mobile Roaming | C8: P3 | D8: Non | J8: Catalogue initial
A9: Voix | B9: SMS Postpaid | C9: P2 | D9: Oui | E9: Daset | F9: 623756095 / 623756112 | J9: Catalogue initial
A10: Voix | B10: SMS Prepaid | C10: P3 | D10: Oui | E10: Daset | F10: 623756095 / 623756112 | J10: Catalogue initial
A11: Voix | B11: SMS Roaming | C11: P3 | D11: Non | J11: Catalogue initial
A12: Voix | B12: Registration 2G / 3G | D12: Oui | E12: Daset | F12: 628414773 / 628414762 / 628414707 / 623755856 / 623755751 / 623755566 / 629694225 / 623755714 / 628414704 | I12: PRIORITÉ À RENSEIGNER (absente du tableau source). | J12: Catalogue initial
A13: Orange Money Core | B13: Consultation 5 dernières transactions Retailer | C13: P2 | D13: Oui | E13: Kapptivate | F13: 627898106 | J13: Catalogue initial
A14: Orange Money Core | B14: Achat de pass pour soi | C14: P1 | D14: Oui | E14: Kapptivate | F14: 627898103 | J14: Catalogue initial
A15: Orange Money Core | B15: Achat de crédit pour tiers | C15: P3 | D15: Oui | E15: Kapptivate | F15: 627898103 | J15: Catalogue initial
A16: Orange Money Core | B16: Achat de pass pour tiers | C16: P1 | D16: Oui | E16: Kapptivate | F16: 627898102 | J16: Catalogue initial
A17: Orange Money Core | B17: C2C Distributeur | C17: P1 | D17: Oui | E17: Kapptivate | F17: 627898106 | J17: Catalogue initial
A18: Orange Money Core | B18: C2C Marchand | C18: P1 | D18: Oui | E18: Kapptivate | F18: 627898100 | J18: Catalogue initial
A19: Orange Money Core | B19: Cash IN Distributeur | C19: P1 | D19: Oui | E19: Kapptivate | F19: 627898106 | J19: Catalogue initial
A20: Orange Money Core | B20: Cash IN Marchand | C20: P1 | D20: Oui | E20: Kapptivate | F20: 627898104 | J20: Catalogue initial
A21: Orange Money Core | B21: Cash OUT | C21: P1 | D21: Oui | E21: Kapptivate | F21: 627898106 | J21: Catalogue initial
A22: Orange Money Core | B22: Changement code secret | C22: P2 | D22: Oui | E22: Kapptivate | F22: 627898105 | J22: Catalogue initial
A23: Orange Money Core | B23: Consultation 10 dernières transactions OM | C23: P2 | D23: Oui | E23: Kapptivate | F23: 627898102 | J23: Catalogue initial
A24: Orange Money Core | B24: Consultation 5 dernières transactions Marchand | C24: P2 | D24: Oui | E24: Kapptivate | F24: 627898100 | J24: Catalogue initial
... A35: Orange Money Core | B35: Consultation solde Retailer (PDV) | C35: P2 | D35: Oui | E35: Kapptivate | F35: 627898106 | J35: Catalogue initial
A36: Orange Money add-on Local | B36: Orange Énergie | C36: P1 | D36: Oui | E36: Kapptivate | I36: SIM de test à renseigner. | J36: Catalogue initial
A37: Orange Money add-on Local | B37: Permis | C37: P1 | D37: Oui | E37: Kapptivate | I37: SIM de test à renseigner. | J37: Catalogue initial
A38: Orange Money add-on Local | B38: Finadev | C38: P1 | D38: Oui | E38: Kapptivate | I38: SIM de test à renseigner. | J38: Catalogue initial
A39: Orange Money add-on Local | B39: Internet Illimity | C39: P3 | D39: Oui | E39: Kapptivate | F39: 629651153 | J39: Catalogue initial
A40: Orange Money add-on Local | B40: CMA-CGM | C40: P1 | D40: Oui | E40: Kapptivate | F40: 627898103 | J40: Catalogue initial
A41: Orange Money add-on Local | B41: CRG (crédit rural) | C41: P1 | D41: Oui | E41: Kapptivate | F41: 627898102 | J41: Catalogue initial
A42: Orange Money add-on Local | B42: Consultation frais de retrait | C42: P3 | D42: Oui | E42: Kapptivate | F42: 627898101 | J42: Catalogue initial
A43: Orange Money add-on Local | B43: Déblocage compte | C43: P2 | D43: Oui | E43: Kapptivate | F43: 627898105 | J43: Catalogue initial
A44: Orange Money add-on Local | B44: EDG | C44: P1 | D44: Oui | E44: Kapptivate | F44: 627898104 | J44: Catalogue initial
A45: Orange Money add-on Local | B45: Guinée Games | C45: P1 | D45: Oui | E45: Kapptivate | F45: 627898104 | J45: Catalogue initial
A46: Orange Money add-on Local | B46: Identification compte | C46: P2 | D46: Oui | E46: Kapptivate | F46: 627898099 | J46: Catalogue initial
A47: Orange Money add-on Local | B47: Lafarge Client | C47: P2 | D47: Oui | E47: Kapptivate | F47: 627898099 | J47: Catalogue initial
A48: Orange Money add-on Local | B48: Lafarge Marchand | C48: P1 | D48: Oui | E48: Kapptivate | F48: 627898100 | J48: Catalogue initial
A49: Orange Money add-on Local | B49: Lanala Assurance | C49: P2 | D49: Oui | E49: Kapptivate | F49: 627898099 | J49: Catalogue initial
A50: Orange Money add-on Local | B50: LightBox Africa | C50: P3 | D50: Oui | E50: Kapptivate | F50: 627898099 | J50: Catalogue initial
... A60: Orange Money add-on Local | B60: YellowBet | C60: P1 | D60: Oui | E60: Kapptivate | F60: 627898099 | J60: Catalogue initial
...

Sheet Comparatif Kapptivate
A1: Catégorie(s) Kapptivate | B1: Service Kapptivate | C1: Technologie(s) | D1: Occurrences export | E1: Domaine — meilleure correspondance | F1: Service — meilleure correspondance | G1: Score de similarité | H1: Statut
A2: PICO | B2: Pico - Inscription USSD | D2: 1 | E2: SVA USSD | F2: Consultation SMS | G2: 0.59459459 | H2: Nouveau — ajouté au catalogue
A3: Nimba Plus | B3: Nimba Plus_API_Transaction OM | D3: 1 | E3: Orange Money Core | F3: Validation transaction OM | G3: 0.59259259 | H3: Nouveau — ajouté au catalogue
A4: VOIX NUMERO COURT | B4: Plateau Orange Money | D4: 1 | E4: Orange Money add-on Local | F4: Facture Orange | G4: 0.58823529 | H4: Nouveau — ajouté au catalogue
A5: OM Bank to Wallet | B5: VistaGUI | D5: 1 | E5: Orange Money add-on Group | F5: VistaBank | G5: 0.58823529 | H5: Nouveau — ajouté au catalogue
A6: OM Addons Locaux | B6: Droits Routiers | D6: 1 | E6: Orange Money Core | F6: Achat de crédit pour tiers | G6: 0.58536585 | H6: Nouveau — ajouté au catalogue
A7: OM Bank to Wallet | B7: CORIS Bank - B2W | D7: 1 | E7: Orange Money add-on Group | F7: Ecobank | G7: 0.57142857 | H7: Nouveau — ajouté au catalogue
A8: OM Bank to Wallet | B8: CORIS Bank - W2B | D8: 1 | E8: Orange Money add-on Group | F8: Ecobank | G8: 0.57142857 | H8: Nouveau — ajouté au catalogue
A9: Data 3G, Data 4G | B9: HTTP google | C9: 4G/3G | D9: 2 | E9: Autres SVA | F9: Google RCS | G9: 0.57142857 | H9: Nouveau — ajouté au catalogue
A10: SVA Data | B10: MAGOE.FR | D10: 1 | E10: Orange Money add-on Local | F10: Maersk | G10: 0.57142857 | H10: Nouveau — ajouté au catalogue
A11: PICO | B11: Pico - Credit Tik Tak | D11: 1 | E11: Orange Money add-on Local | F11: CRG (crédit rural) | G11: 0.57142857 | H11: Nouveau — ajouté au catalogue
A12: OM Bank to Wallet | B12: VistaGUI - B2W | D12: 1 | E12: Orange Money add-on Group | F12: VistaBank | G12: 0.57142857 | H12: Nouveau — ajouté au catalogue
A13: OM Bank to Wallet | B13: VistaGUI - W2B | D13: 1 | E13: Orange Money add-on Group | F13: VistaBank | G13: 0.57142857 | H13: Nouveau — ajouté au catalogue
A14: Data Social Network | B14: FACEBOOK | C14: 4G/3G | D14: 1 | E14: Orange Money add-on Group | F14: AccessBank | G14: 0.55555556 | H14: Nouveau — ajouté au catalogue
A15: Data Social Network | B15: INSTAGRAM | C15: 4G/3G | D15: 1 | E15: Orange Money add-on Local | F15: StarTimes | G15: 0.55555556 | H15: Nouveau — ajouté au catalogue
A16: PICO | B16: Pico - Transfert Vers OM | D16: 1 | E16: SVA USSD | F16: Transfert DATA | G16: 0.55555556 | H16: Nouveau — ajouté au catalogue
A17: OM Addons Group | B17: Portail Distributeurs Orange Money | D17: 1 | E17: Orange Money Core | F17: Cash IN Distributeur | G17: 0.55555556 | H17: Nouveau — ajouté au catalogue
A18: OM Bank to Wallet | B18: BNIG - B2W | D18: 1 | E18: Orange Money add-on Group | F18: BIG | G18: 0.54545455 | H18: Nouveau — ajouté au catalogue
A19: OM Bank to Wallet | B19: BNIG - W2B | D19: 1 | E19: Orange Money add-on Group | F19: BIG | G19: 0.54545455 | H19: Nouveau — ajouté au catalogue
A20: OM Bank to Wallet | B20: DIAMABANK-B2W | D20: 1 | E20: Orange Money add-on Group | F20: VistaBank | G20: 0.54545455 | H20: Nouveau — ajouté au catalogue
A21: OM Bank to Wallet | B21: DIAMABANK-W2B | D21: 1 | E21: Orange Money add-on Group | F21: VistaBank | G21: 0.54545455 | H21: Nouveau — ajouté au catalogue
A22: OM Bank to Wallet | B22: AFG BANK B2W | D22: 1 | E22: Orange Money add-on Group | F22: FBNBank | G22: 0.52631579 | H22: Nouveau — ajouté au catalogue
A23: OM Bank to Wallet | B23: AFG BANK W2B | D23: 1 | E23: Orange Money add-on Group | F23: FBNBank | G23: 0.52631579 | H23: Nouveau — ajouté au catalogue
A24: OUTILS SI | B24: CRM(KIBARU) | D24: 1 | E24: ZEBRA | F24: RMS Zebra | G24: 0.52631579 | H24: Nouveau — ajouté au catalogue
A25: SVA USSD | B25: Vérification Nombre Abonnement Telco | D25: 1 | E25: Orange Money add-on Local | F25: Identification compte | G25: 0.52631579 | H25: Nouveau — ajouté au catalogue
A26: Audit Facturation | B26: Appel Swagg to OnNet ORANGE | D26: 1 | E26: Autres SVA | F26: Site web Orange | G26: 0.52380952 | H26: Nouveau — ajouté au catalogue
A27: Nimba Plus | B27: Nimba Plus_API_Authentification | D27: 1 | E27: Orange Money add-on Local | F27: Self identification | G27: 0.52 | H27: Nouveau — ajouté au catalogue
... A29: OM Addons Group | B29: Global Reporting | D29: 1 | E29: SVA USSD | F29: Report Avantage | G29: 0.51612903 | H29: Nouveau — ajouté au catalogue
A30: Data 3G, Data 4G | B30: TRACEROUTE kapptivate | C30: 4G/3G | D30: 2 | E30: SVA USSD | F30: Transfert DATA | G30: 0.51428571 | H30: Nouveau — ajouté au catalogue
A31: OUTILS SI | B31: Distrinet_Commande | D31: 1 | E31: Orange Money add-on Local | F31: Identification compte | G31: 0.51282051 | H31: Nouveau — ajouté au catalogue
A32: OUTILS SI | B32: Distrinet_Encaissement | D32: 1 | E32: Orange Money add-on Local | F32: Internet Illimity | G32: 0.51282051 | H32: Nouveau — ajouté au catalogue
A33: SVA Data | B33: API OTAP | D33: 1 | E33: Orange Money Core | F33: Cash OUT | G33: 0.5 | H33: Nouveau — ajouté au catalogue
A34: Audit Facturation | B34: Appel CMO to OnNet ORANGE | D34: 1 | E34: Autres SVA | F34: Site web Orange | G34: 0.5 | H34: Nouveau — ajouté au catalogue
A35: SVA SMS | B35: CMS | D35: 1 | E35: SVA USSD | F35: Achat SMS | G35: 0.5 | H35: Nouveau — ajouté au catalogue
A36: Data 3G, Data 4G | B36: DL | C36: 4G/3G | D36: 2 | E36: Orange Money add-on Local | F36: MedLog | G36: 0.5 | H36: Nouveau — ajouté au catalogue
A37: OM Addons Locaux | B37: Douane REDEVANCE | D37: 1 | E37: Orange Money add-on Local | F37: Lanala Assurance | G37: 0.5 | H37: Nouveau — ajouté au catalogue
A38: Data 3G, Data 4G | B38: HTTP daset | C38: 4G/3G | D38: 2 | E38: SVA USSD | F38: Achat pass | G38: 0.5 | H38: Nouveau — ajouté au catalogue
A39: Data Social Network | B39: MESSENGER | C39: 4G/3G | D39: 1 | E39: Orange Money add-on Local | F39: SEG | G39: 0.5 | H39: Nouveau — ajouté au catalogue
A40: SVA USSD | B40: Menu OM | D40: 1 | E40: Orange Money add-on Local | F40: Partenaire OM | G40: 0.5 | H40: Nouveau — ajouté au catalogue
A41: OM Addons Locaux | B41: Mouna | D41: 1 | E41: Orange Money add-on Group | F41: Coffina | G41: 0.5 | H41: Nouveau — ajouté au catalogue
...

Sheet Reclassement SVA
A1: RECLASSEMENT DES SERVICES « AUTRES SVA »
A2: « Autres SVA » n'est pas un type de produit — les services qui correspondent clairement à une catégorie Kapptivate précise (SVA USSD, SVA SMS, SVA Data) ont été déplacés vers ce domaine. Seuil de reclassement automatique : 60% de similarité avec un service Kapptivate de la catégorie visée.
A4: Service | B4: Ancien domaine | C4: Nouveau domaine | D4: Correspondance Kapptivate | E4: Score
A5: Playweez | B5: Autres SVA | C5: SVA Data | D5: PLAYWEEZ 1 | E5: 0.97
A6: Playciné | B6: Autres SVA | C6: SVA Data | D6: PLAYCINE 1 | E6: 0.97
A7: YouScribe | B7: Autres SVA | C7: SVA Data | D7: YOUSCRIBE 1 | E7: 0.97
A8: Mobile TV | B8: Autres SVA | C8: SVA Data | D8: Mobile Academy | E8: 0.60869565
A9: SimBackup (sauvegarde répertoire) | B9: Autres SVA | C9: SVA SMS | D9: SIMBackup | E9: 0.97
A10: SMS API (Paddock) | B10: Autres SVA | C10: SVA SMS | D10: Paddock SMS | E10: 0.95
A11: Achat pass | B11: Autres SVA | C11: SVA USSD | D11: Achat Pass | E11: 1
A12: Achat SMS | B12: Autres SVA | C12: SVA USSD | D12: Achat SMS | E12: 1
A13: Achat pass tiers | B13: Autres SVA | C13: SVA USSD | D13: Achat de Pass pour Tiers | E13: 1
A14: Call Shine | B14: Autres SVA | C14: SVA USSD | D14: Call Shine | E14: 1
A15: Consultation solde | B15: Autres SVA | C15: SVA USSD | D15: Consultation Solde | E15: 1
A16: Fun Voice | B16: Autres SVA | C16: SVA USSD | D16: Fun Voice | E16: 1
... A32: Transfert DATA | B32: Autres SVA | C32: SVA USSD | D32: Tr DATA | E32: 0.66666667

Sheet MaxIt (canal alternatif)
A1: MAXIT — CANAL ALTERNATIF, PAS UNE FAMILLE DE SERVICES
A2: MaxIt est une plateforme web donnant accès à des services déjà catalogués ailleurs (Orange Money, SVA...). Ces 34 entrées ne sont donc PAS ajoutées au catalogue comme nouveaux services. Cette liste sert à vérifier que chaque service accessible via MaxIt est bien couvert par ailleurs — colonne « À couvrir via MaxIt ? » à trancher.
A4: Service (libellé MaxIt) | B4: Domaine — meilleure correspondance | C4: Service — meilleure correspondance | D4: Score | E4: Correspondance jugée fiable | F4: À couvrir via MaxIt ? | G4: Commentaire
A5: MaxIt-Achat pass pour soi Telco | B5: SVA USSD | C5: Achat pass | D5: 0.97 | E5: Oui
A6: Maxit - Paiement Marchand | B6: Orange Money Core | C6: Paiement Marchand | D6: 0.97 | E6: Oui
A7: Maxit-Achat pass pour soi OM | B7: SVA USSD | C7: Achat pass | D7: 0.97 | E7: Oui
A8: Maxit-Forfait choco telco | B8: SVA USSD | C8: Forfait Choco | D8: 0.97 | E8: Oui
A9: Maxit-Playcine | B9: SVA Data | C9: Playciné | D9: 0.97 | E9: Oui
A10: Maxit-Playweez | B10: SVA Data | C10: Playweez | D10: 0.97 | E10: Oui
A11: Maxit-Youscribe | B11: SVA Data | C11: YouScribe | D11: 0.97 | E11: Oui
A12: Maxit-achat pass pour tiers OM | B12: SVA USSD | C12: Achat pass | D12: 0.97 | E12: Oui
A13: Maxit-forfait choco OM | B13: SVA USSD | C13: Forfait Choco | D13: 0.97 | E13: Oui
A14: Maxit-OrangeJeux | B14: Autres SVA | C14: Orange Jeux | D14: 0.74074074 | E14: Oui
A15: YMO Africa | B15: Orange Money add-on Group | C15: OM App Africa | D15: 0.69565217 | E15: Oui
A16: Maxit-Recharge credit fix OM | B16: Orange Money Core | C16: Recharge (achat de crédit via OM) | D16: 0.6779661 | E16: Oui
... A38: Maxit-Full Univers - With Auth | B38: Orange Money add-on Group | C38: API B2B Cash Minute | D38: 0.38297872 | E38: Non

Sheet À vérifier
A1: SERVICES À VÉRIFIER MANUELLEMENT
A2: Score de similarité entre 60% et 89% (hors MaxIt, traité à part) : ressemblance repérée automatiquement mais pas assez fiable pour trancher seul.
A4: Catégorie Kapptivate | B4: Service Kapptivate | C4: Domaine catalogue (approché) | D4: Service catalogue (approché) | E4: Score | F4: Décision | G4: Commentaire
A5: OM Core | B5: Recharge (Achat de credit pour soi OM) | C5: Orange Money Core | D5: Recharge (achat de crédit via OM) | E5: 0.86567164
A6: OM Bank to Wallet | B6: BNIG | C6: Orange Money add-on Group | D6: BIG | E6: 0.85714286
A7: OM Addons Group | B7: APIB2B CASH IN | C7: Orange Money add-on Group | D7: API B2B Cash Minute | E7: 0.84848485
A8: SVA SMS | B8: CallShine_SMS | C8: SVA USSD | D8: Call Shine | E8: 0.7826087
A9: Data Social Network | B9: WhatsApp Mobile | C9: Voix | D9: Data Mobile | E9: 0.76923077
A10: OM Core | B10: Self Reinitialisation | C10: Orange Money add-on Local | D10: Self identification | E10: 0.75
A11: Data 4G, SVA Data | B11: HTTP Identification Client | C11: Orange Money add-on Local | D11: Identification compte | E11: 0.72340426
A12: OM Core | B12: Consul 10 dern trans OM | C12: Orange Money Core | D12: Consultation 10 dernières transactions OM | E12: 0.71875
A13: OM Addons Locaux | B13: Remboursement Marchand | C13: Orange Money Core | D13: Paiement Marchand | E13: 0.71794872
A14: OM Addons Locaux | B14: Ya!GAZ Marchand | C14: Orange Money add-on Local | D14: Lafarge Marchand | E14: 0.70967742
A15: OM Bank to Wallet | B15: CORIS Bank | C15: Orange Money add-on Group | D15: Ecobank | E15: 0.70588235
A16: OM Bank to Wallet | B16: Cofina - B2W | C16: Orange Money add-on Group | D16: Coffina | E16: 0.70588235
... A39: SVA USSD | B39: Portail Islamique | C39: SVA USSD | D39: Portail Magic | E39: 0.6

Sheet Doublons Kapptivate
A1: DOUBLONS RÉSIDUELS DANS L'EXPORT KAPPTIVATE
A2: 8 services apparaissent plusieurs fois dans le fichier source, hors sondes 3G/4G (déjà fusionnées automatiquement — voir Légende §2).
A4: Service | B4: Nb occurrences | C4: Catégorie(s) où il apparaît | D4: Type de doublon
A5: Downdetector cellular FACEBOOK | B5: 2 | C5: Downdetector / Downdetector | D5: Ligne répétée dans la même catégorie
A6: Downdetector cellular WHATSAPP | B6: 2 | C6: Downdetector / Downdetector | D6: Ligne répétée dans la même catégorie
A7: Downdetector cellular MESSENGER | B7: 2 | C7: Downdetector / Downdetector | D7: Ligne répétée dans la même catégorie
A8: Downdetector cellular TELEGRAM | B8: 2 | C8: Downdetector / Downdetector | D8: Ligne répétée dans la même catégorie
A9: Downdetector cellular TIKTOK | B9: 2 | C9: Downdetector / Downdetector | D9: Ligne répétée dans la même catégorie
A10: Downdetector cellular INSTAGRAM | B10: 2 | C10: Downdetector / Downdetector | D10: Ligne répétée dans la même catégorie
A11: Downdetector cellular X(TWITTER) | B11: 2 | C11: Downdetector / Downdetector | D11: Ligne répétée dans la même catégorie
A12: AGED DocuWare | B12: 2 | C12: Nimba Plus / OUTILS SI | D12: Service listé dans plusieurs catégories

Sheet Points d'attention
A1: POINTS D'ATTENTION ET ANOMALIES RELEVÉES
A2: Écarts constatés lors de la mise en forme du catalogue et de l'intégration de l'export Kapptivate.
A4: N° | B4: Type | C4: Service concerné | D4: Constat | E4: Décision / action | F4: Statut
A5: 1 | B5: Règle de conformité | C5: Autres SVA → SVA USSD/SMS/Data | D5: 28 services reclassés depuis « Autres SVA » (qui n'est pas un type de produit) vers les vraies catégories Kapptivate SVA USSD / SVA SMS / SVA Data, sur preuve de correspondance ≥60%. Détail dans l'onglet « Reclassement SVA ». | E5: Traité | F5: Traité
A6: 2 | B6: À arbitrer | C6: 12 services restant en « Autres SVA » | D6: Aucune correspondance Kapptivate suffisamment fiable (<60%) pour les reclasser automatiquement : E-Shop, E-recharge via BaySIM, FFC (Football Fans Club), Friend and Family, Google RCS, Molotov, Orange & Moi (web et app mobile), Orange Jeux, Paie pour Moi (M4P), SMSPRO (Pack Smart Pro), SOS Crédit, Site web Orange. À trancher manuellement si l'un d'eux relève en réalité d'une catégorie SVA précise.
A7: 3 | B7: Couverture | C7: 6 services P1 (version initiale) | D7: Prepaid Voix, AccessBank, API B2B BNB, API B2B Cash Minute, API B2B Wely Wely, Bonus Program (IRIS) : priorité critique, aucune supervision déclarée dans le document source initial.
A8: 4 | B8: Bonne nouvelle à confirmer | C8: AccessBank | D8: L'export Kapptivate contient des sondes « AccessBank-B2W » et « AccessBank-W2B » (≥90% de similarité avec « AccessBank »). Le service semble donc supervisé en réalité — à confirmer avant de retirer l'alerte P1.
A9: 5 | B9: Doublon | C9: VDC | D9: Présent deux fois dans le tableau source initial (P3 et P2). Fusionné, priorité retenue : P2. | E9: Traité — P2 retenue | F9: Traité
A10: 6 | B10: Règle de conformité | C10: Sondes 3G/4G | D10: 24 sondes « 3G | X » et « 4G | X » fusionnées en une seule ligne par service (même service, deux technologies), conformément à la précision fournie. | E10: Traité | F10: Traité
A11: 7 | B11: Règle de conformité | C11: MaxIt | D11: 34 entrées « Maxit-… » exclues du catalogue comme nouveaux services : MaxIt est un canal web alternatif, pas une famille de services. Recensées dans l'onglet dédié pour vérification de couverture. | E11: Traité | F11: Traité
A12: 8 | B12: Règle de conformité | C12: Priorité par défaut P1 | D12: 53 nouveaux services Orange Money / SVA USSD / SVA SMS / PICO sans priorité définie mis à P1 par défaut, conformément à la règle fournie. | E12: Traité | F12: Traité
A13: 9 | B13: Doublon export Kapptivate | C13: 8 services | D13: Voir l'onglet « Doublons Kapptivate » (répétitions Downdetector, et un service rattaché à deux catégories).
A14: 10 | B14: À arbitrer | C14: 35 services | D14: Ressemblance 60-89% entre un service Kapptivate et un service du catalogue existant. Voir l'onglet « À vérifier ».
A15: 11 | B15: Donnée manquante | C15: Registration 2G / 3G | D15: Aucune priorité renseignée dans le document source alors que le service est supervisé.
A16: 12 | B16: Donnée manquante | C16: RMS Zebra | D16: Aucune priorité renseignée et aucune supervision déclarée.
