Workbook
Name cat: #REF!
Name d: #REF!
Name g: #REF!
Name ORIGINE: #REF!
Name porteur: #REF!
Name prio: #REF!
Name Réinitialiser_Zone_Impression: OFFSET(#REF!,0,0,COUNTA(#REF!)+5)
Name s: #REF!
Name stat: #REF!
Name SurlignageTâchesÀFaire: #REF!
Name SurlignerActivités: #REF!
Name valHDébut: #REF!
Name valHFin: #REF!

Sheet Plan d'action
A1: N° | B1: PA | C1: Porteur | D1: Date d'affection | E1: Deadline | F1: Date de realisation | G1: Durée
A2: 1 | G2: =F2-D2 -> 0
A3: 2
A4: 3
A5: 4
A6: 5
A7: 6
A8: 7
A9: 8
A10: 9
A11: 10

Sheet Suivi Perfomances
B2: Team | C2: Performances | D2: Jan | E2: Fev | F2: Mar | G2: Avr | H2: Mai | I2: Juin | J2: Juillet | K2: Août | L2: Sept | M2: Oct | N2: Nov | O2: Déc | P2: Total | Q2: Moy Global
B3: Alpho D | C3: % PA Soldés | P3: 0.4 | Q3: =AVERAGE(P3:P7) -> 0.68
C4: Nombre Incidents | P4: 0.7
C5: % Reception et archivage RI | P5: 1
C6: % Cloture des TQ | P6: 1
C7: Taux d'atteintes des Objectifs | P7: 0.3
B8: Keita | C8: % PA Soldés | P8: 0.5 | Q8: =AVERAGE(P8:P12) -> 0.7
C9: Nombre Incidents | P9: 0.7
C10: % Reception et archivage RI | P10: 1
C11: % Cloture des TQ | P11: 1
C12: Taux d'atteintes des Objectifs | P12: 0.3
B13: Alpha B | C13: % PA Soldés | P13: 0.4 | Q13: =AVERAGE(P13:P17) -> 0.68
C14: Nombre Incidents | P14: 0.8
C15: % Reception et archivage RI | P15: 0.9
C16: % Cloture des TQ | P16: 1
C17: Taux d'atteintes des Objectifs | P17: 0.3
B18: Bobo | C18: % PA Soldés | P18: 0.3 | Q18: =AVERAGE(P18:P22) -> 0.66
C19: Nombre Incidents | P19: 0.7
C20: % Reception et archivage RI | P20: 1
C21: % Cloture des TQ | P21: 1
C22: Taux d'atteintes des Objectifs | P22: 0.3

Sheet Objectifs_2022
B1: Objectifs 2022
A2: N° | B2: Nom | C2: Commentaire | D2: Periode
A3: 1 | B3: Vulgarisation de l'utilisation des outils calipso (Swan et Oceane), Helios et brise | D3: S2
A4: 2 | B4: Mise à jour de la base Marine des Produits (automatisation si possible) | D4: S2
A5: 3 | B5: Mise à jour de la base Marine des ressources (automatisation si possible) | D5: S2
A6: 4 | B6: Création de la dépendance ressource - produit et produit-produit | D6: S2
A7: 5 | B7: Mise à jour des reporting des incidents, problemes, plaintes et changement sur brise | D7: S2
A8: 6 | B8: Mise à Jour du Catalogue OGN Swan dans Marine (association des impacts (dépendance) par operation depuis la création du TQ) | D8: S2
A9: 7 | B9: Mise en place d'un tableau de Bord Supervision des incident et ATP sur Helios | D9: S2
A10: 8 | B10: Automatisation des notifications (mail et SMS) de la gestion des Incidents (la signalisation des incidents vers les TMC et le CCC) | D10: S2
A11: 9 | B11: Développement de l'outil central de Knowledge Management des différentes supervisions (Services, Huawei, GNOC et IPT) | D11: S2
A12: 10 | B12: POC Supervision du reseau (RAN, Network IP, Data Mobile et VAS) avec ELK (Elasticsearch & Kibana), | D12: S2
A13: 11 | B13: Mise en place de la supervision du réseaux IP sur OPMANAGER | D13: S2
A14: 12 | B14: Mise en place de la supervision du réseaux IP sur Prometheus & Grafana | D14: S2
... A16: 14 | B16: Mise à jour des fiches Consigne existantes et Elaboration des fiches de certains services | D16: S2

Sheet JANVIER_2026
A1: N° | B1: N°ticket | C1: Priorité | D1: Origine | E1: Nom de service | F1: Début | G1: Fin retablissement | H1: Fin réparation | I1: Durée rétablissement (hh:mn) | J1: Durée rétablissement (mn) | K1: Durée réparation (hh:mn) | L1: Durée réparation (mn) | M1: Description | N1: Cause de l'incident | O1: Actions correctives | P1: TMC | Q1: Statut | R1: Observation | S1: SLA | T1: Exlusion | U1: RI
A2: 1 | B2: 2601Q38109 | C2: P1 | D2: Supervision | E2: Orange Money add-on Local / EDG Prepaid | F2: 46023.733 | G2: 46024.24 | H2: 46024.24 | I2: =G2-F2 -> 0.50763889 | J2: =I2*1440 -> 731 | K2: =H2-F2 -> 0.50763889 | L2: =K2*1440 -> 731 | M2: Impossible d'effectuer des paiements de facture EDG via Orange Money | N2: Inconnue | O2: Inconnue | P2: DSI | Q2: Clos | S2: =IF(AND(C2="P1",J2<=240),"ISLA",IF((AND(C2="P2",J2<=480)),"ISLA",IF((AND(C2="P3",J2<=2880)),"ISLA","OSLA"))) -> OSLA | T2: =IF((AND(MID(P2,1,2)="IT",S2="OSLA")),"OUI","NON") -> NON | U2: NON
A3: 2 | B3: 2601Q39915 | C3: P1 | D3: Supervision | E3: Orange Money add-on / Bank to Wallet / FBNBank | F3: 46023.735 | G3: 46023.982 | H3: 46023.982 | I3: =G3-F3 -> 0.24722222 | J3: =I3*1440 -> 356 | K3: =H3-F3 -> 0.24722222 | L3: =K3*1440 -> 356 | M3: Impossible d’effectuer des transactions bancaires FBNBank via Orange Money | N3: Inconnue | O3: Inconnue | P3: IT FBNBANK | Q3: Clos | S3: =IF(AND(C3="P1",J3<=240),"ISLA",IF((AND(C3="P2",J3<=480)),"ISLA",IF((AND(C3="P3",J3<=2880)),"ISLA","OSLA"))) -> OSLA | T3: =IF((AND(MID(P3,1,2)="IT",S3="OSLA")),"OUI","NON") -> OUI | U3: Pas de RI
A4: 3 | B4: 2601Q41376 | C4: P1 | D4: Supervision | E4: Orange Money add-on Locaux / Douane REDEVANCE / Contravention_GN | F4: 46023.838 | G4: 46023.876 | H4: 46023.876 | I4: =G4-F4 -> 0.038888889 | J4: =I4*1440 -> 56 | K4: =H4-F4 -> 0.038888889 | L4: =K4*1440 -> 56 | M4: Indisponibilité du service Douane REDEVANCE et Contravention GN | N4: Inconnue | O4: Inconnue | P4: IT NGSER | Q4: Clos | S4: =IF(AND(C4="P1",J4<=240),"ISLA",IF((AND(C4="P2",J4<=480)),"ISLA",IF((AND(C4="P3",J4<=2880)),"ISLA","OSLA"))) -> ISLA | T4: =IF((AND(MID(P4,1,2)="IT",S4="OSLA")),"OUI","NON") -> NON | U4: Pas de RI
A5: 4 | B5: 2601Q52339 | C5: P1 | D5: Supervision | E5: Orange Money add-on Local / CRG | F5: 46024.392 | G5: 46024.417 | H5: 46024.417 | I5: =G5-F5 -> 0.024305556 | J5: =I5*1440 -> 35 | K5: =H5-F5 -> 0.024305556 | L5: =K5*1440 -> 35 | M5: Impossible pour le client de faire des épargnes via Orange money | N5: Inconnue | O5: Inconnue | P5: IT CRG | Q5: Clos | S5: =IF(AND(C5="P1",J5<=240),"ISLA",IF((AND(C5="P2",J5<=480)),"ISLA",IF((AND(C5="P3",J5<=2880)),"ISLA","OSLA"))) -> ISLA | T5: =IF((AND(MID(P5,1,2)="IT",S5="OSLA")),"OUI","NON") -> NON | U5: Pas de RI
A6: 5 | B6: 2601Q55215 & 2601Q57185 | C6: P1 | D6: Supervision | E6: Orange Money add-on Locaux | Nimba Plus | F6: 46024.438 | G6: 46025.417 | H6: 46025.417 | I6: =G6-F6 -> 0.97916667 | J6: =I6*1440 -> 1410 | K6: =H6-F6 -> 0.97916667 | L6: =K6*1440 -> 1410 | M6: Instabilité sur plusieurs services Orange Money Addons-Locaux et Nimba Plus | N6: Problème de certificat observés sur plusieurs micro-services | O6: Une solution de contournement pour faire passer toutes les rêquetes https en http sur les intances de kira | P6: DSI | Q6: Clos | S6: =IF(AND(C6="P1",J6<=240),"ISLA",IF((AND(C6="P2",J6<=480)),"ISLA",IF((AND(C6="P3",J6<=2880)),"ISLA","OSLA"))) -> OSLA | T6: =IF((AND(MID(P6,1,2)="IT",S6="OSLA")),"OUI","NON") -> NON | U6: NON
A7: 6 | B7: 2601Q78476 | C7: P1 | D7: Supervision | E7: Orange Money add-on Local / Identification Compte | F7: 46025.41 | G7: 46025.618 | H7: 46025.618 | I7: =G7-F7 -> 0.20833333 | J7: =I7*1440 -> 300 | K7: =H7-F7 -> 0.20833333 | L7: =K7*1440 -> 300 | M7: Impossible pour les clients d'identifier leur compte Orange Money via le *144# | N7: Inconnue | O7: Inconnue | P7: DSI | Q7: Clos | S7: =IF(AND(C7="P1",J7<=240),"ISLA",IF((AND(C7="P2",J7<=480)),"ISLA",IF((AND(C7="P3",J7<=2880)),"ISLA","OSLA"))) -> OSLA | T7: =IF((AND(MID(P7,1,2)="IT",S7="OSLA")),"OUI","NON") -> NON | U7: NON
A8: 7 | B8: 2601Q81413 | C8: P1 | D8: Supervision | E8: Orange Money add-on Locaux | Nimba Plus | F8: 46025.476 | G8: 46025.514 | H8: 46025.514 | I8: =G8-F8 -> 0.038194444 | J8: =I8*1440 -> 55 | K8: =H8-F8 -> 0.038194444 | L8: =K8*1440 -> 55 | M8: Instabilité sur plusieurs services Orange Money Addons-Locaux et Nimba Plus | N8: Problème de certificat sur les instances de kira | O8: Inconnue | P8: DSI | Q8: Clos | S8: =IF(AND(C8="P1",J8<=240),"ISLA",IF((AND(C8="P2",J8<=480)),"ISLA",IF((AND(C8="P3",J8<=2880)),"ISLA","OSLA"))) -> ISLA | T8: =IF((AND(MID(P8,1,2)="IT",S8="OSLA")),"OUI","NON") -> NON | U8: NON
A9: 8 | B9: 2601Q81730 | C9: P1 | D9: Supervision | E9: Orange Money add-on Locaux / Guinée GAMES TICKET / Lafarge Client / Lanala Assurance / Ouverture de compte OM / PayCard / School Fees USSD / YellowBet Orange Money Core / Achat Forfait Choco pour soi OM / Achat Forfait Choco pour tiers OM / Achat de credit pour tiers OM & Consul 10 dern trans OM | F9: 46025.528 | G9: 46025.615 | H9: 46025.615 | I9: =G9-F9 -> 0.086805556 | J9: =I9*1440 -> 125 | K9: =H9-F9 -> 0.086805556 | L9: =K9*1440 -> 125 | M9: Indisponibilité de plusieurs services Orange Money add-on-Locaux et Orange Money Core | N9: Inconnue | O9: Inconnue | P9: DSI | Q9: Clos | S9: =IF(AND(C9="P1",J9<=240),"ISLA",IF((AND(C9="P2",J9<=480)),"ISLA",IF((AND(C9="P3",J9<=2880)),"ISLA","OSLA"))) -> ISLA | T9: =IF((AND(MID(P9,1,2)="IT",S9="OSLA")),"OUI","NON") -> NON | U9: NON
A10: 9 | B10: 2601Q87978 & 2601R21759 | C10: P1 | D10: Supervision | E10: Orange Money add-on Locaux / Minigrid_Souscription / Minigrid_Paiement / UGAR-ACTIVA / School Fees USSD / MSC_GUI / Mouna / UBIPHARM Client / UBIPHARM Marchand / Paycard | Nimba Plus_API_SETTINGS / Nimba Plus_API_TELCO / Nimba Plus_API_Transaction OM & Big Data Check MSISDN Frequent hbase | F10: 46025.802 | G10: 46029.005 | H10: 46029.005 | I10: =G10-F10 -> 3.2027778 | J10: =I10*1440 -> 4612 | K10: =H10-F10 -> 3.2027778 | L10: =K10*1440 -> 4612 | M10: Instabilité de plusieurs services Orange Money Add-ons Locaux, Nimba Plus & Outils SI | N10: Souci sur Kira | O10: Inconnue | P10: DSI | Q10: Clos | S10: =IF(AND(C10="P1",J10<=240),"ISLA",IF((AND(C10="P2",J10<=480)),"ISLA",IF((AND(C10="P3",J10<=2880)),"ISLA","OSLA"))) -> OSLA | T10: =IF((AND(MID(P10,1,2)="IT",S10="OSLA")),"OUI","NON") -> NON | U10: NON
A11: 10 | B11: 2511Z13777 | C11: P1 | D11: Supervision | E11: Orange Money add-on Locaux / UBIPHARM Client & Marchand | F11: 46026.052 | G11: 46026.257 | H11: 46026.257 | I11: =G11-F11 -> 0.20486111 | J11: =I11*1440 -> 295 | K11: =H11-F11 -> 0.20486111 | L11: =K11*1440 -> 295 | M11: Impossible pour les clients et marchands de UBIPHARM de payer leur facture via Orange Money | N11: Inconnue | O11: Inconnue | P11: DSI | Q11: Clos | S11: =IF(AND(C11="P1",J11<=240),"ISLA",IF((AND(C11="P2",J11<=480)),"ISLA",IF((AND(C11="P3",J11<=2880)),"ISLA","OSLA"))) -> OSLA | T11: =IF((AND(MID(P11,1,2)="IT",S11="OSLA")),"OUI","NON") -> NON | U11: NON
A12: 11 | B12: 2601Q97232 | C12: P1 | D12: Supervision | E12: Orange Money add-on / Bank to Wallet / FBNBank | F12: 46026.389 | G12: 46026.764 | H12: 46026.764 | I12: =G12-F12 -> 0.375 | J12: =I12*1440 -> 540 | K12: =H12-F12 -> 0.375 | L12: =K12*1440 -> 540 | M12: Impossible d’effectuer des transactions bancaires FBNBank via Orange Money | N12: Inconnue | O12: Inconnue | P12: IT FBNBANK | Q12: Clos | S12: =IF(AND(C12="P1",J12<=240),"ISLA",IF((AND(C12="P2",J12<=480)),"ISLA",IF((AND(C12="P3",J12<=2880)),"ISLA","OSLA"))) -> OSLA | T12: =IF((AND(MID(P12,1,2)="IT",S12="OSLA")),"OUI","NON") -> OUI | U12: Pas de RI
A13: 12 | B13: 2601R16562 | C13: P1 | D13: Supervision | E13: Orange Money add-on Local / Contravention_GN | F13: 46027.367 | G13: 46027.406 | H13: 46027.406 | I13: =G13-F13 -> 0.038888889 | J13: =I13*1440 -> 56 | K13: =H13-F13 -> 0.038888889 | L13: =K13*1440 -> 56 | M13: Indisponibilité du service Contravention GN | N13: Inconnue | O13: Inconnue | P13: IT NGSER | Q13: Clos | S13: =IF(AND(C13="P1",J13<=240),"ISLA",IF((AND(C13="P2",J13<=480)),"ISLA",IF((AND(C13="P3",J13<=2880)),"ISLA","OSLA"))) -> ISLA | T13: =IF((AND(MID(P13,1,2)="IT",S13="OSLA")),"OUI","NON") -> NON | U13: Pas de RI
... A132: 131 | B132: 2601A12810 | C132: P1 | D132: Supervision | E132: Orange Money add-on / Bank to Wallet / NSIA | F132: 46053.64 | G132: 46053.692 | H132: 46053.692 | I132: =G132-F132 -> 0.051388889 | J132: =I132*1440 -> 74 | K132: =H132-F132 -> 0.051388889 | L132: =K132*1440 -> 74 | M132: Impossible d’effectuer des transactions bancaires NSIA via Orange Money | N132: Inconnue | O132: Inconnue | P132: IT NSIA | Q132: Clos | S132: =IF(AND(C132="P1",J132<=240),"ISLA",IF((AND(C132="P2",J132<=480)),"ISLA",IF((AND(C132="P3",J132<=2880)),"ISLA","OSLA"))) -> ISLA | T132: =IF((AND(MID(P132,1,2)="IT",S132="OSLA")),"OUI","NON") -> NON | U132: Pas de RI

Sheet Synthese_2018
A1: Overview | P1: Priorité | AD1: TMC
B3: Jan | C3: Jan | D3: Fev | E3: Mars | F3: Avril | G3: Mai | H3: Juin | I3: Juillet | J3: Août | K3: Sept | L3: Oct | M3: Nov | N3: Dec | Q3: Jan | R3: Fev | S3: Mars | T3: Avril | U3: Mai | V3: Juin | W3: Juillet | X3: Août | Y3: Sept | Z3: Oct | AA3: Nov | AB3: Dec | AE3: Jan | AF3: Fev | AG3: Mars | AH3: Avril | AI3: Mai | AJ3: Juin | AK3: Juillet | AL3: Août | AM3: Sept | AN3: Oct | AO3: Nov | AP3: Dec
A4: Nombre d'incidents | C4: =COUNTA(Janvier_2018!C2:C37) -> 31 | D4: =COUNTA(Février_2018!C2:C29) -> 28 | E4: =COUNTA(Mars_2018!C2:C41) -> 40 | F4: =COUNTA(Avril_2018!C2:C44) -> 43 | G4: =COUNTA(Mai_2018!C2:C30) -> 29 | H4: =COUNTA(Juin_2018!C2:C45) -> 44 | I4: =COUNTA(Juillet_2018!C2:C17) -> 16 | J4: =COUNTA(Aout_2018!C2:C45) -> 22 | K4: =COUNTA(Septembre_2018!C2:C20) -> 15 | L4: =COUNTA(Octobre_2018!C2:C41) -> 40 | M4: =COUNTA(Novembre_2018!C2:C48) -> 47 | N4: =COUNTA(Decembre_2018!C2:C54) -> 53 | P4: P1 | Q4: =COUNTIF(Janvier_2018!C:C,"=P1") -> 26 | R4: =COUNTIF(Février_2018!C:C,"=P1") -> 20 | S4: =COUNTIF(Mars_2018!C:C,"=P1") -> 27 | T4: =COUNTIF(Avril_2018!C:C,"=P1") -> 37 | U4: =COUNTIF(Mai_2018!C:C,"=P1") -> 24 | V4: =COUNTIF(Juin_2018!C:C,"=P1") -> 33 | W4: =COUNTIF(Juillet_2018!C:C,"=P1") -> 15 | X4: =COUNTIF(Aout_2018!C:C,"=P1") -> 19 | Y4: =COUNTIF(Septembre_2018!C:C,"=P1") -> 12 | Z4: =COUNTIF(Octobre_2018!C:C,"=P1") -> 36 | AA4: =COUNTIF(Novembre_2018!C:C,"=P1") -> 43 | AB4: =COUNTIF(Decembre_2018!C:C,"=P1") -> 48 | AD4: GIN | AE4: =COUNTIF(Janvier_2018!$L:$L,"GIN") -> 0 | AF4: =COUNTIF(Février_2018!$L:$L,"GIN") -> 0 | AG4: =COUNTIF(Mars_2018!$L:$L,"GIN") -> 0 | AH4: =COUNTIF(Avril_2018!$L:$L,"GIN") -> 0 | AI4: =COUNTIF(Mai_2018!$L:$L,"GIN") -> 0 | AJ4: =COUNTIF(Juin_2018!$L:$L,"GIN") -> 0 | AK4: =COUNTIF(Juillet_2018!$L:$L,"GIN") -> 0 | AL4: =COUNTIF(Aout_2018!$L:$L,"GIN") -> 0 | AM4: =COUNTIF(Septembre_2018!$L:$L,"GIN") -> 0 | AN4: =COUNTIF(Octobre_2018!$L:$L,"GIN") -> 0 | AO4: =COUNTIF(Novembre_2018!$L:$L,"GIN") -> 0 | AP4: =COUNTIF(Decembre_2018!$L:$L,"GIN") -> 0
A5: InSLA | C5: =COUNTIF(Janvier_2018!$O$2:$O$32,"ISLA") -> 17 | D5: =COUNTIF(Février_2018!$O$2:$O$29,"ISLA") -> 15 | E5: =+COUNTIF(Mars_2018!$O$2:$O$41,"ISLA") -> 26 | F5: =COUNTIF(Avril_2018!$O$2:$O$44,"ISLA") -> 34 | G5: =+COUNTIF(Mai_2018!$O$2:$O$30,"ISLA") -> 22 | H5: =+COUNTIF(Juin_2018!$O$2:$O$45,"ISLA") -> 27 | I5: =COUNTIF(Juillet_2018!$O$2:$O$45,"ISLA") -> 11 | J5: =COUNTIF(Aout_2018!$O$2:$O$45,"ISLA") -> 12 | K5: =COUNTIF(Septembre_2018!$O$2:$O$20,"ISLA") -> 11 | L5: =COUNTIF(Octobre_2018!$O$2:$O$41,"ISLA") -> 25 | M5: =COUNTIF(Novembre_2018!$O$2:$O$48,"ISLA") -> 29 | N5: =COUNTIF(Decembre_2018!$O$2:$O$54,"ISLA") -> 36 | P5: P2 | Q5: =COUNTIF(Janvier_2018!C:C,"=P2") -> 4 | R5: =COUNTIF(Février_2018!C:C,"=P2") -> 7 | S5: =COUNTIF(Mars_2018!C:C,"=P2") -> 8 | T5: =COUNTIF(Avril_2018!C:C,"=P2") -> 5 | U5: =COUNTIF(Mai_2018!C:C,"=P2") -> 5 | V5: =COUNTIF(Juin_2018!C:C,"=P2") -> 11 | W5: =COUNTIF(Juillet_2018!C:C,"=P2") -> 0 | X5: =COUNTIF(Aout_2018!C:C,"=P2") -> 3 | Y5: =COUNTIF(Septembre_2018!C:C,"=P2") -> 3 | Z5: =COUNTIF(Octobre_2018!C:C,"=P2") -> 4 | AA5: =COUNTIF(Novembre_2018!C:C,"=P2") -> 4 | AB5: =COUNTIF(Decembre_2018!C:C,"=P2") -> 5 | AD5: SSPO | AE5: =COUNTIF(Janvier_2018!$L:$L,"SSPO") -> 16 | AF5: =COUNTIF(Février_2018!$L:$L,"SSPO") -> 8 | AG5: =COUNTIF(Mars_2018!$L:$L,"SSPO") -> 17 | AH5: =COUNTIF(Avril_2018!$L:$L,"SSPO") -> 19 | AI5: =COUNTIF(Mai_2018!$L:$L,"SSPO") -> 12 | AJ5: =COUNTIF(Juin_2018!$L:$L,"SSPO") -> 17 | AK5: =COUNTIF(Juillet_2018!$L:$L,"SSPO") -> 7 | AL5: =COUNTIF(Aout_2018!$L:$L,"SSPO") -> 15 | AM5: =COUNTIF(Septembre_2018!$L:$L,"SSPO") -> 8 | AN5: =COUNTIF(Octobre_2018!$L:$L,"SSPO") -> 19 | AO5: =COUNTIF(Novembre_2018!$L:$L,"SSPO") -> 21 | AP5: =COUNTIF(Decembre_2018!$L:$L,"SSPO") -> 30
A6: OutofSLA | C6: =COUNTIF(Janvier_2018!$O$2:$O$32,"oSLA") -> 14 | D6: =COUNTIF(Février_2018!$O$2:$O$29,"OSLA") -> 13 | E6: =+COUNTIF(Mars_2018!$O$2:$O$41,"OSLA") -> 14 | F6: =COUNTIF(Avril_2018!$O$2:$O$44,"OSLA") -> 9 | G6: =+COUNTIF(Mai_2018!$O$2:$O$30,"OSLA") -> 7 | H6: =+COUNTIF(Juin_2018!$O$2:$O$45,"OSLA") -> 17 | I6: =COUNTIF(Juillet_2018!$O$2:$O$45,"OSLA") -> 5 | J6: =COUNTIF(Aout_2018!$O$2:$O$45,"OSLA") -> 10 | K6: =COUNTIF(Septembre_2018!$O$2:$O$20,"OSLA") -> 4 | L6: =COUNTIF(Octobre_2018!$O$2:$O$41,"OSLA") -> 14 | M6: =COUNTIF(Novembre_2018!$O$2:$O$48,"OSLA") -> 18 | N6: =COUNTIF(Decembre_2018!$O$2:$O$54,"OSLA") -> 17 | P6: P3 | Q6: =COUNTIF(Janvier_2018!C:C,"=P3") -> 1 | R6: =COUNTIF(Février_2018!C:C,"=P3") -> 1 | S6: =COUNTIF(Mars_2018!C:C,"=P3") -> 5 | T6: =COUNTIF(Avril_2018!C:C,"=P3") -> 1 | U6: =COUNTIF(Mai_2018!C:C,"=P3") -> 0 | V6: =COUNTIF(Juin_2018!C:C,"=P3") -> 0 | W6: =COUNTIF(Juillet_2018!C:C,"=P3") -> 1 | X6: =COUNTIF(Aout_2018!C:C,"=P3") -> 0 | Y6: =COUNTIF(Septembre_2018!C:C,"=P3") -> 0 | Z6: =COUNTIF(Octobre_2018!C:C,"=P3") -> 0 | AA6: =COUNTIF(Novembre_2018!C:C,"=P3") -> 0 | AB6: =COUNTIF(Decembre_2018!C:C,"=P3") -> 0 | AD6: GOS | AE6: =COUNTIF(Janvier_2018!$L:$L,"GOS") -> 6 | AF6: =COUNTIF(Février_2018!$L:$L,"GOS") -> 9 | AG6: =COUNTIF(Mars_2018!$L:$L,"GOS") -> 4 | AH6: =COUNTIF(Avril_2018!$L:$L,"GOS") -> 5 | AI6: =COUNTIF(Mai_2018!$L:$L,"GOS") -> 1 | AJ6: =COUNTIF(Juin_2018!$L:$L,"GOS") -> 4 | AK6: =COUNTIF(Juillet_2018!$L:$L,"GOS") -> 0 | AL6: =COUNTIF(Aout_2018!$L:$L,"GOS") -> 1 | AM6: =COUNTIF(Septembre_2018!$L:$L,"GOS") -> 1 | AN6: =COUNTIF(Octobre_2018!$L:$L,"GOS") -> 2 | AO6: =COUNTIF(Novembre_2018!$L:$L,"GOS") -> 3 | AP6: =COUNTIF(Decembre_2018!$L:$L,"GOS") -> 8
A7: Nombre d'incidents causés par TP | C7: 5 | D7: 1 | E7: 3 | F7: 1 | G7: 0 | H7: 1 | I7: 0 | J7: 0 | K7: 1 | L7: 2 | M7: 0 | N7: 0 | P7: P4 | Q7: =COUNTIF(Janvier_2018!C:C,"=P4") -> 0 | R7: =COUNTIF(Février_2018!C:C,"=P4") -> 0 | S7: =COUNTIF(Mars_2018!C:C,"=P4") -> 0 | T7: =COUNTIF(Avril_2018!C:C,"=P4") -> 0 | U7: =COUNTIF(Mai_2018!C:C,"=P4") -> 0 | V7: =COUNTIF(Juin_2018!C:C,"=P4") -> 0 | W7: =COUNTIF(Juillet_2018!C:C,"=P4") -> 0 | X7: =COUNTIF(Aout_2018!C:C,"=P4") -> 0 | Y7: =COUNTIF(Septembre_2018!C:C,"=P4") -> 0 | Z7: =COUNTIF(Octobre_2018!C:C,"=P4") -> 0 | AA7: =COUNTIF(Novembre_2018!C:C,"=P4") -> 0 | AB7: =COUNTIF(Decembre_2018!C:C,"=P4") -> 0 | AD7: GNOC | AE7: =COUNTIF(Janvier_2018!$L:$L,"GNOC") -> 4 | AF7: =COUNTIF(Février_2018!$L:$L,"GNOC") -> 4 | AG7: =COUNTIF(Mars_2018!$L:$L,"GNOC") -> 6 | AH7: =COUNTIF(Avril_2018!$L:$L,"GNOC") -> 4 | AI7: =COUNTIF(Mai_2018!$L:$L,"GNOC") -> 7 | AJ7: =COUNTIF(Juin_2018!$L:$L,"GNOC") -> 5 | AK7: =COUNTIF(Juillet_2018!$L:$L,"GNOC") -> 5 | AL7: =COUNTIF(Aout_2018!$L:$L,"GNOC") -> 2 | AM7: =COUNTIF(Septembre_2018!$L:$L,"GNOC") -> 3 | AN7: =COUNTIF(Octobre_2018!$L:$L,"GNOC") -> 2 | AO7: =COUNTIF(Novembre_2018!$L:$L,"GNOC") -> 11 | AP7: =COUNTIF(Decembre_2018!$L:$L,"GNOC") -> 4
A8: MTTR | C8: =(SUM(COUNTIFS(Janvier_2018!C:C,"=P1",Janvier_2018!H:H,"<=120"),COUNTIFS(Janvier_2018!C:C,"=P2",Janvier_2018!H:H,"<=240"),COUNTIFS(Janvier_2018!C:C,"=P3",Janvier_2018!H:H,"<=2880")))/(SUM(COUNTIF(Janvier_2018!C:C,"=P1"),COUNTIF(Janvier_2018!C:C,"=P2"),COUNTIF(Janvier_2018!C:C,"=P3"))) -> 0.5483871 | D8: =(SUM(COUNTIFS(Février_2018!C:C,"=P1",Février_2018!H:H,"<=120"),COUNTIFS(Février_2018!C:C,"=P2",Février_2018!H:H,"<=240"),COUNTIFS(Février_2018!C:C,"=P3",Février_2018!H:H,"<=2880")))/(SUM(COUNTIF(Février_2018!C:C,"=P1"),COUNTIF(Février_2018!C:C,"=P2"),COUNTIF(Février_2018!C:C,"=P3"))) -> 0.53571429 | E8: =(SUM(COUNTIFS(Mars_2018!C:C,"=P1",Mars_2018!H:H,"<=120"),COUNTIFS(Mars_2018!C:C,"=P2",Mars_2018!H:H,"<=240"),COUNTIFS(Mars_2018!C:C,"=P3",Mars_2018!H:H,"<=2880")))/(SUM(COUNTIF(Mars_2018!C:C,"=P1"),COUNTIF(Mars_2018!C:C,"=P2"),COUNTIF(Mars_2018!C:C,"=P3"))) -> 0.65 | F8: =(SUM(COUNTIFS(Avril_2018!C:C,"=P1",Avril_2018!H:H,"<=120"),COUNTIFS(Avril_2018!C:C,"=P2",Avril_2018!H:H,"<=240"),COUNTIFS(Avril_2018!C:C,"=P3",Avril_2018!H:H,"<=2880")))/(SUM(COUNTIF(Avril_2018!C:C,"=P1"),COUNTIF(Avril_2018!C:C,"=P2"),COUNTIF(Avril_2018!C:C,"=P3"))) -> 0.79069767 | G8: =(SUM(COUNTIFS(Mai_2018!C:C,"=P1",Mai_2018!H:H,"<=120"),COUNTIFS(Mai_2018!C:C,"=P2",Mai_2018!H:H,"<=240"),COUNTIFS(Mai_2018!C:C,"=P3",Mai_2018!H:H,"<=2880")))/(SUM(COUNTIF(Mai_2018!C:C,"=P1"),COUNTIF(Mai_2018!C:C,"=P2"),COUNTIF(Mai_2018!C:C,"=P3"))) -> 0.75862069 | H8: =(SUM(COUNTIFS(Juin_2018!C:C,"=P1",Juin_2018!H:H,"<=120"),COUNTIFS(Juin_2018!C:C,"=P2",Juin_2018!H:H,"<=240"),COUNTIFS(Juin_2018!C:C,"=P3",Juin_2018!H:H,"<=2880")))/(SUM(COUNTIF(Juin_2018!C:C,"=P1"),COUNTIF(Juin_2018!C:C,"=P2"),COUNTIF(Juin_2018!C:C,"=P3"))) -> 0.61363636 | I8: =(SUM(COUNTIFS(Juillet_2018!C:C,"=P1",Juillet_2018!H:H,"<=120"),COUNTIFS(Juillet_2018!C:C,"=P2",Juillet_2018!H:H,"<=240"),COUNTIFS(Juillet_2018!C:C,"=P3",Juillet_2018!H:H,"<=2880")))/(SUM(COUNTIF(Juillet_2018!C:C,"=P1"),COUNTIF(Juillet_2018!C:C,"=P2"),COUNTIF(Juillet_2018!C:C,"=P3"))) -> 0.6875 | J8: =(SUM(COUNTIFS(Aout_2018!C:C,"=P1",Aout_2018!H:H,"<=120"),COUNTIFS(Aout_2018!C:C,"=P2",Aout_2018!H:H,"<=240"),COUNTIFS(Aout_2018!C:C,"=P3",Aout_2018!H:H,"<=2880")))/(SUM(COUNTIF(Aout_2018!C:C,"=P1"),COUNTIF(Aout_2018!C:C,"=P2"),COUNTIF(Aout_2018!C:C,"=P3"))) -> 0.54545455 | K8: =(SUM(COUNTIFS(Septembre_2018!C:C,"=P1",Septembre_2018!H:H,"<=120"),COUNTIFS(Septembre_2018!C:C,"=P2",Septembre_2018!H:H,"<=240"),COUNTIFS(Septembre_2018!C:C,"=P3",Septembre_2018!H:H,"<=2880")))/(SUM(COUNTIF(Septembre_2018!C:C,"=P1"),COUNTIF(Septembre_2018!C:C,"=P2"),COUNTIF(Septembre_2018!C:C,"=P3"))) -> 0.73333333 | L8: =(SUM(COUNTIFS(Octobre_2018!C:C,"=P1",Octobre_2018!H:H,"<=120"),COUNTIFS(Octobre_2018!C:C,"=P2",Octobre_2018!H:H,"<=240"),COUNTIFS(Octobre_2018!C:C,"=P3",Octobre_2018!H:H,"<=2880")))/(SUM(COUNTIF(Octobre_2018!C:C,"=P1"),COUNTIF(Octobre_2018!C:C,"=P2"),COUNTIF(Octobre_2018!C:C,"=P3"))) -> 0.65 | M8: =(SUM(COUNTIFS(Novembre_2018!C:C,"=P1",Novembre_2018!H:H,"<=120"),COUNTIFS(Novembre_2018!C:C,"=P2",Novembre_2018!H:H,"<=240"),COUNTIFS(Novembre_2018!C:C,"=P3",Novembre_2018!H:H,"<=2880")))/(SUM(COUNTIF(Novembre_2018!C:C,"=P1"),COUNTIF(Novembre_2018!C:C,"=P2"),COUNTIF(Novembre_2018!C:C,"=P3"))) -> 0.61702128 | N8: =(SUM(COUNTIFS(Decembre_2018!C:C,"=P1",Decembre_2018!H:H,"<=120"),COUNTIFS(Decembre_2018!C:C,"=P2",Decembre_2018!H:H,"<=240"),COUNTIFS(Decembre_2018!C:C,"=P3",Decembre_2018!H:H,"<=2880")))/(SUM(COUNTIF(Decembre_2018!C:C,"=P1"),COUNTIF(Decembre_2018!C:C,"=P2"),COUNTIF(Decembre_2018!C:C,"=P3"))) -> 0.66037736 | P8: Total | Q8: =SUM(Q4:Q7) -> 31 | R8: =SUM(R4:R7) -> 28 | S8: =SUM(S4:S7) -> 40 | T8: =SUM(T4:T7) -> 43 | U8: =SUM(U4:U7) -> 29 | V8: =SUM(V4:V7) -> 44 | W8: =SUM(W4:W7) -> 16 | X8: =SUM(X4:X7) -> 22 | ... AB8: =SUM(AB4:AB7) -> 53 | AD8: ASBD | AE8: =COUNTIF(Janvier_2018!$L:$L,"ASBD") -> 2 | AF8: =COUNTIF(Février_2018!$L:$L,"ASBD") -> 2 | AG8: =COUNTIF(Mars_2018!$L:$L,"ASBD") -> 4 | AH8: =COUNTIF(Avril_2018!$L:$L,"ASBD") -> 8 | AI8: =COUNTIF(Mai_2018!$L:$L,"ASBD") -> 3 | AJ8: =COUNTIF(Juin_2018!$L:$L,"ASBD") -> 3 | AK8: =COUNTIF(Juillet_2018!$L:$L,"ASBD") -> 1 | AL8: =COUNTIF(Aout_2018!$L:$L,"ASBD") -> 2 | AM8: =COUNTIF(Septembre_2018!$L:$L,"ASBD") -> 1 | AN8: =COUNTIF(Octobre_2018!$L:$L,"ASBD") -> 11 | AO8: =COUNTIF(Novembre_2018!$L:$L,"ASBD") -> 6 | AP8: =COUNTIF(Decembre_2018!$L:$L,"ASBD") -> 3
AD9: DevOps | AE9: =COUNTIF(Janvier_2018!$L:$L,"PSIVAS") -> 1 | AF9: =COUNTIF(Février_2018!$L:$L,"DevOps") -> 0 | AG9: =COUNTIF(Mars_2018!$L:$L,"DevOps") -> 0 | AH9: =COUNTIF(Avril_2018!$L:$L,"DevOps") -> 0 | AI9: =COUNTIF(Mai_2018!$L:$L,"DevOps") -> 0 | AJ9: =COUNTIF(Juin_2018!$L:$L,"DevOps") -> 2 | AK9: =COUNTIF(Juillet_2018!$L:$L,"DevOps") -> 0 | AL9: =COUNTIF(Aout_2018!$L:$L,"DevOps") -> 0 | AM9: =COUNTIF(Septembre_2018!$L:$L,"DevOps") -> 1 | AN9: =COUNTIF(Octobre_2018!$L:$L,"DevOps") -> 0 | AO9: =COUNTIF(Novembre_2018!$L:$L,"DevOps") -> 0 | AP9: =COUNTIF(Decembre_2018!$L:$L,"DevOps") -> 3
A11: Service | P11: Statut | AD11: TPS vs trafic
B13: Jan | C13: Jan | D13: Fev | E13: Mars | F13: Avril | G13: Mai | H13: Juin | I13: Juillet | J13: Août | K13: Sept | L13: Oct | M13: Nov | N13: Dec | Q13: Jan | R13: Fev | S13: Mars | T13: Avril | U13: Mai | V13: Juin | W13: Juillet | X13: Août | Y13: Sept | Z13: Oct | AA13: Nov | AB13: Dec | AE13: Jan | AF13: Fev | AG13: Mars | AH13: Avril | AI13: Mai | AJ13: Juin | AK13: Juillet | AL13: Août | AM13: Sept | AN13: Oct | AO13: Nov
A14: E-recharge | C14: =COUNTIF(Janvier_2018!$E$2:$E$32,"*E-recharge*") -> 3 | D14: =COUNTIF(Février_2018!$E$2:$E$45,"*E-recharge*") -> 1 | E14: =COUNTIF(Mars_2018!$E$2:$E$45,"*E-recharge*") -> 2 | F14: =COUNTIF(Avril_2018!$E$2:$E$45,"*E-recharge*") -> 4 | G14: =COUNTIF(Mai_2018!$E$2:$E$45,"*E-recharge*") -> 6 | H14: =COUNTIF(Juin_2018!$E$2:$E$45,"*E-recharge*") -> 9 | I14: =COUNTIF(Juillet_2018!$E$2:$E$45,"*E-recharge*") -> 2 | J14: =COUNTIF(Aout_2018!$E$2:$E$45,"*E-recharge*") -> 0 | K14: =COUNTIF(Septembre_2018!$E$2:$E$45,"*E-recharge*") -> 0 | L14: =COUNTIF(Octobre_2018!$E$2:$E$46,"*E-recharge*") -> 3 | M14: =COUNTIF(Novembre_2018!$I$2:$I$48,"*E-recharge*") -> 6 | N14: =COUNTIF(Novembre_2018!$I$2:$I$54,"*E-recharge*") -> 6 | P14: En cours | Q14: =COUNTIF(Janvier_2018!$M$2:$M$45,"En cours") -> 0 | R14: =COUNTIF(Février_2018!$M$2:$M$45,"En cours") -> 0 | S14: =COUNTIF(Mars_2018!$M$2:$M$45,"En cours") -> 0 | T14: =COUNTIF(Avril_2018!$M$2:$M$45,"En cours") -> 0 | U14: =COUNTIF(Mai_2018!$M$2:$M$45,"En cours") -> 0 | V14: =COUNTIF(Juin_2018!$M$2:$M$45,"En cours") -> 0 | W14: =COUNTIF(Juillet_2018!$M$2:$M$45,"En cours") -> 0 | X14: =COUNTIF(Aout_2018!$M$2:$M$45,"En cours") -> 0 | Y14: =COUNTIF(Septembre_2018!$M$2:$M$20,"En cours") -> 0 | Z14: =COUNTIF(Octobre_2018!$M$2:$M$41,"En cours") -> 0 | AA14: =COUNTIF(Novembre_2018!$M$2:$M$48,"En cours") -> 0 | AB14: =COUNTIF(Decembre_2018!$M$2:$M$53,"En cours") -> 1 | AD14: Trafic
A15: Orange Money | C15: =COUNTIF(Janvier_2018!$E$2:$E$32,"*Orange Money*") -> 13 | D15: =COUNTIF(Février_2018!$E$2:$E$45,"*Orange Money*") -> 7 | E15: =COUNTIF(Mars_2018!$E$2:$E$45,"*Orange Money*") -> 18 | F15: =COUNTIF(Avril_2018!$E$2:$E$45,"*Orange Money*") -> 20 | G15: =COUNTIF(Mai_2018!$E$2:$E$45,"*Orange Money*") -> 11 | H15: =COUNTIF(Juin_2018!$E$2:$E$45,"*Orange Money*") -> 15 | I15: =COUNTIF(Juillet_2018!$E$2:$E$45,"*Orange Money*") -> 7 | J15: =COUNTIF(Aout_2018!$E$2:$E$45,"*Orange Money*") -> 16 | K15: =COUNTIF(Septembre_2018!$E$2:$E$45,"*Orange Money*") -> 4 | L15: =COUNTIF(Octobre_2018!$E$2:$E$46,"*Orange Money*") -> 19 | M15: =COUNTIF(Novembre_2018!$E$2:$E$48,"*Orange Money*") -> 25 | N15: =COUNTIF(Novembre_2018!$E$2:$E$54,"*Orange Money*") -> 25 | P15: clos | Q15: =COUNTIF(Janvier_2018!$M$2:$M$45,"Clos") -> 31 | R15: =COUNTIF(Février_2018!$M$2:$M$45,"Clos") -> 28 | S15: =COUNTIF(Mars_2018!$M$2:$M$45,"Clos") -> 40 | T15: =COUNTIF(Avril_2018!$M$2:$M$45,"Clos") -> 43 | U15: =COUNTIF(Mai_2018!$M$2:$M$45,"Clos") -> 29 | V15: =COUNTIF(Juin_2018!$M$2:$M$45,"Clos") -> 44 | W15: =COUNTIF(Juillet_2018!$M$2:$M$45,"Clos") -> 16 | X15: =COUNTIF(Aout_2018!$M$2:$M$45,"Clos") -> 22 | Y15: =COUNTIF(Septembre_2018!$M$2:$M$20,"Clos") -> 15 | Z15: =COUNTIF(Octobre_2018!$M$2:$M$41,"Clos") -> 39 | AA15: =COUNTIF(Novembre_2018!$M$2:$M$48,"Clos") -> 47 | AB15: =COUNTIF(Decembre_2018!$M$2:$M$54,"Clos") -> 52 | AD15: TPS
A16: Internet | C16: =COUNTIF(Janvier_2018!$E$2:$E$32,"*Data mobile*") -> 2 | D16: =COUNTIF(Février_2018!$E$2:$E$45,"*Data mobile*") -> 2 | E16: =COUNTIF(Mars_2018!$E$2:$E$45,"*Data mobile*") -> 2 | F16: =COUNTIF(Avril_2018!$E$2:$E$45,"*Data mobile*") -> 2 | G16: =COUNTIF(Mai_2018!$E$2:$E$45,"*Data mobile*") -> 0 | H16: =COUNTIF(Juin_2018!$E$2:$E$45,"*Data mobile*") -> 0 | I16: =COUNTIF(Juillet_2018!$E$2:$E$45,"*Data mobile*") -> 1 | J16: =COUNTIF(Aout_2018!$E$2:$E$45,"*Data mobile*") -> 1 | K16: =COUNTIF(Septembre_2018!$E$2:$E$45,"*Data mobile*") -> 3 | L16: =COUNTIF(Octobre_2018!$E$2:$E$46,"*Data mobile*") -> 1 | M16: =COUNTIF(Novembre_2018!$I$2:$I$48,"*Data mobile*") -> 0 | N16: =COUNTIF(Novembre_2018!$I$2:$I$54,"*Data mobile*") -> 0 | P16: gélé | Q16: =COUNTIF(Janvier_2018!$M$2:$M$45,"gele") -> 0 | R16: =COUNTIF(Février_2018!$M$2:$M$45,"gele") -> 0 | S16: =COUNTIF(Mars_2018!$M$2:$M$45,"gele") -> 0 | T16: =COUNTIF(Avril_2018!$M$2:$M$45,"gele") -> 0 | U16: =COUNTIF(Mai_2018!$M$2:$M$45,"gele") -> 0 | V16: =COUNTIF(Juin_2018!$M$2:$M$45,"gele") -> 0 | W16: =COUNTIF(Juillet_2018!$M$2:$M$45,"gele") -> 0 | X16: =COUNTIF(Aout_2018!$M$2:$M$45,"gele") -> 0 | Y16: =COUNTIF(Septembre_2018!$M$2:$M$20,"gele") -> 0 | Z16: =COUNTIF(Octobre_2018!$M$2:$M$41,"gele") -> 0 | AA16: =COUNTIF(Novembre_2018!$M$2:$M$48,"gele") -> 0 | AB16: =COUNTIF(Decembre_2018!$M$2:$M$53,"gele") -> 0
A17: Voix | C17: =COUNTIF(Janvier_2018!$E$2:$E$32,"*VOIX*") -> 2 | D17: =COUNTIF(Février_2018!$E$2:$E$45,"*VOIX*") -> 0 | E17: =COUNTIF(Mars_2018!$E$2:$E$45,"*VOIX*") -> 1 | F17: =COUNTIF(Avril_2018!$E$2:$E$45,"*VOIX*") -> 0 | G17: =COUNTIF(Mai_2018!$E$2:$E$45,"*VOIX*") -> 1 | H17: =COUNTIF(Juin_2018!$E$2:$E$45,"*VOIX*") -> 3 | I17: =COUNTIF(Juillet_2018!$E$2:$E$45,"*VOIX*") -> 2 | J17: =COUNTIF(Aout_2018!$E$2:$E$45,"*VOIX*") -> 0 | K17: =COUNTIF(Septembre_2018!$E$2:$E$45,"*VOIX*") -> 0 | L17: =COUNTIF(Octobre_2018!$E$2:$E$46,"*VOIX*") -> 0 | M17: =COUNTIF(Novembre_2018!$I$2:$I$48,"*VOIX*") -> 3 | N17: =COUNTIF(Novembre_2018!$I$2:$I$54,"*VOIX*") -> 3
A18: SMS | C18: =COUNTIF(Janvier_2018!$E$2:$E$32,"*SMS*") -> 1 | D18: =COUNTIF(Février_2018!$E$2:$E$45,"*SMS*") -> 4 | E18: =COUNTIF(Mars_2018!$E$2:$E$45,"*SMS*") -> 0 | F18: =COUNTIF(Avril_2018!$E$2:$E$45,"*SMS*") -> 3 | G18: =COUNTIF(Mai_2018!$E$2:$E$45,"*SMS*") -> 2 | H18: =COUNTIF(Juin_2018!$E$2:$E$45,"*SMS*") -> 1 | I18: =COUNTIF(Juillet_2018!$E$2:$E$45,"*SMS*") -> 2 | J18: =COUNTIF(Aout_2018!$E$2:$E$45,"*SMS*") -> 0 | K18: =COUNTIF(Septembre_2018!$E$2:$E$45,"*SMS*") -> 1 | L18: =COUNTIF(Octobre_2018!$E$2:$E$46,"*SMS*") -> 1 | M18: =COUNTIF(Novembre_2018!$I$2:$I$48,"*SMS*") -> 5 | N18: =COUNTIF(Novembre_2018!$I$2:$I$54,"*SMS*") -> 5
A19: VAS | C19: =C4-(C14+C15+C16+C17+C18+C20+C21+C22) -> 10 | D19: =D4-(D14+D15+D16+D17+D18+D20+D21+D22) -> 13 | E19: =E4-(E14+E15+E16+E17+E18+E20+E21+E22) -> 17 | F19: =F4-(F14+F15+F16+F17+F18+F20+F21+F22) -> 14 | G19: =G4-(G14+G15+G16+G17+G18+G20+G21+G22) -> 9 | H19: =H4-(H14+H15+H16+H17+H18+H20+H21+H22) -> 16 | I19: =I4-(I14+I15+I16+I17+I18+I20+I21+I22) -> 2 | J19: =J4-(J14+J15+J16+J17+J18+J20+J21+J22) -> 4 | ... N19: =N4-(N14+N15+N16+N17+N18+N20+N21+N22) -> 14
A20: Roaming voix | C20: =COUNTIF(Janvier_2018!$E$2:$E$45,"*Roaming voix*") -> 0 | D20: =COUNTIF(Février_2018!$E$2:$E$45,"*Roaming voix*") -> 0 | E20: =COUNTIF(Mars_2018!$E$2:$E$45,"*Roaming voix*") -> 0 | F20: =COUNTIF(Avril_2018!$E$2:$E$45,"*Roaming voix*") -> 0 | G20: =COUNTIF(Mai_2018!$E$2:$E$45,"*Roaming voix*") -> 0 | H20: =COUNTIF(Juin_2018!$E$2:$E$45,"*Roaming voix*") -> 0 | I20: =COUNTIF(Juillet_2018!$E$2:$E$45,"*Roaming voix*") -> 0 | J20: =COUNTIF(Aout_2018!$E$2:$E$45,"*Roaming voix*") -> 0 | K20: =COUNTIF(Septembre_2018!$E$2:$E$45,"*Roaming voix*") -> 0 | L20: =COUNTIF(Octobre_2018!$E$2:$E$46,"*Roaming voix*") -> 0 | M20: =COUNTIF(Novembre_2018!$I$2:$I$48,"*Roaming voix*") -> 0 | N20: =COUNTIF(Novembre_2018!$I$2:$I$54,"*Roaming voix*") -> 0
A21: Roaming data | C21: =COUNTIF(Janvier_2018!$E$2:$E$45,"*Roaming data*") -> 0 | D21: =COUNTIF(Février_2018!$E$2:$E$45,"*Roaming data*") -> 1 | E21: =COUNTIF(Mars_2018!$E$2:$E$45,"*Roaming data*") -> 0 | F21: =COUNTIF(Avril_2018!$E$2:$E$45,"*Roaming data*") -> 0 | G21: =COUNTIF(Mai_2018!$E$2:$E$45,"*Roaming data*") -> 0 | H21: =COUNTIF(Juin_2018!$E$2:$E$45,"*Roaming data*") -> 0 | I21: =COUNTIF(Juillet_2018!$E$2:$E$45,"*Roaming data*") -> 0 | J21: =COUNTIF(Aout_2018!$E$2:$E$45,"*Roaming data*") -> 1 | K21: =COUNTIF(Septembre_2018!$E$2:$E$45,"*Roaming data*") -> 0 | L21: =COUNTIF(Octobre_2018!$E$2:$E$46,"*Roaming data*") -> 0 | M21: =COUNTIF(Novembre_2018!$I$2:$I$48,"*Roaming data*") -> 0 | N21: =COUNTIF(Novembre_2018!$I$2:$I$54,"*Roaming data*") -> 0
A22: Roaming SMS | C22: =COUNTIF(Janvier_2018!$E$2:$E$45,"*Roaming sms*") -> 0 | D22: =COUNTIF(Février_2018!$E$2:$E$45,"*Roaming sms*") -> 0 | E22: =COUNTIF(Mars_2018!$E$2:$E$45,"*Roaming sms*") -> 0 | F22: =COUNTIF(Avril_2018!$E$2:$E$45,"*Roaming sms*") -> 0 | G22: =COUNTIF(Mai_2018!$E$2:$E$45,"*Roaming sms*") -> 0 | H22: =COUNTIF(Juin_2018!$E$2:$E$45,"*Roaming sms*") -> 0 | I22: =COUNTIF(Juillet_2018!$E$2:$E$45,"*Roaming sms*") -> 0 | J22: =COUNTIF(Aout_2018!$E$2:$E$45,"*Roaming sms*") -> 0 | K22: =COUNTIF(Septembre_2018!$E$2:$E$45,"*Roaming sms*") -> 0 | L22: =COUNTIF(Octobre_2018!$E$2:$E$46,"*Roaming sms*") -> 0 | M22: =COUNTIF(Novembre_2018!$I$2:$I$48,"*Roaming sms*") -> 0 | N22: =COUNTIF(Novembre_2018!$I$2:$I$54,"*Roaming sms*") -> 0

Sheet objectifs_Semestre_2_2018
A3: Objectifs | B3: Sem 33 | C3: Sem 34 | D3: Sem 35 | E3: Sem 36 | F3: Sem 37 | G3: Sem 38 | H3: Sem 39 | I3: Sem 40 | J3: Sem 41 | K3: Sem 42 | L3: Sem 43 | M3: Sem 44 | N3: Sem 45 | O3: Sem 46 | P3: Sem 47 | Q3: Sem 48 | R3: Sem 49 | S3: Sem 50 | T3: Sem 51 | U3: Sem 52 | V3: Sem 01 | W3: Sem 02 | X3: Sem 03 | Y3: Sem 04 | Z3: Sem 05 | AA3: Sem 06 | AB3: Sem 07
A4: Faire un suivi journalier des tickets d’incidents en cours avec le GNOC et s’assurer que les rapports d’incidents P1 et P2 sont joints dans océane avant clôture. | B4: 1 | C4: 1 | D4: 1 | E4: 1 | F4: 1 | G4: 1 | H4: 1 | I4: 1 | J4: 1 | K4: 1 | L4: 1 | M4: 1 | N4: 1 | O4: 1 | P4: 1 | Q4: 1 | R4: 1 | S4: 1 | T4: 1 | U4: 1 | V4: - | W4: - | X4: - | Y4: - | Z4: - | AA4: - | AB4: -
A5: Initier les tickets problèmes vers les problem managers pour tous les incidents dont la RC n’est pas connue ou pour toutes récurrences avec les mêmes causes (3 ème récurrence). Relier les tickets d’incident au ticket problème pour une bonne traçabilité | B5: 1 | C5: 1 | D5: 1 | E5: 1 | F5: 1 | G5: 1 | H5: 1 | I5: 1 | J5: 1 | K5: 1 | L5: 1 | M5: 1 | N5: 1 | O5: 1 | P5: 1 | Q5: 1 | R5: 1 | S5: 1 | T5: 1 | U5: 1 | V5: 1 | W5: 1 | X5: 1 | Y5: 1 | Z5: 1 | AA5: 1 | AB5: 1
A6: Fournir le Rapport de pilotage d’incident au (rapport service) à J pour les P1 et P2 y compris les récurrences | B6: - | C6: - | D6: - | E6: - | F6: - | G6: - | H6: - | I6: 1 | J6: - | K6: - | L6: - | M6: 1 | N6: - | O6: - | P6: 1 | Q6: 1 | R6: - | S6: 1 | T6: - | U6: 1 | V6: - | W6: - | X6: - | Y6: - | Z6: - | AA6: - | AB6: -
A7: faire la mise à jour de toutes les architectures reseaux et service ainsi que les chaines de soutien (organiser des ateliers) | B7: NE | C7: NE | D7: NE | E7: NE | F7: NE | G7: NE | H7: NE | I7: 1 | J7: NE | K7: NE | L7: NE | M7: NE | N7: NE | O7: NE | P7: NE | Q7: NE | R7: 1 | S7: NE | T7: NE | U7: NE | V7: NE | W7: NE | X7: NE | Y7: NE | Z7: NE | AA7: NE | AB7: NE
A8: faire le suivi de traitement des alarmes et mettre à jour le fichier | B8: 1 | C8: 1 | D8: 1 | E8: 1 | F8: 1 | G8: 1 | H8: 1 | I8: 1 | J8: 1 | K8: 1 | L8: 1 | M8: 1 | N8: 1 | O8: 1 | P8: 1 | Q8: 1 | R8: 1 | S8: 1 | T8: 1 | U8: 1 | V8: 1 | W8: 1 | X8: 1 | Y8: 1 | Z8: 1 | AA8: 1 | AB8: 1

Sheet Janvier_2018
A1: N° | B1: N°ticket | C1: Priorité | D1: Origine | E1: Nom Service | F1: Date & heure de début | G1: Date & heure de fin | H1: Durée (mn) | I1: Description | J1: Cause de l'incident | K1: Actions correctives | L1: TMC | M1: Statut | N1: Observation | O1: SLA
A2: 1 | B2: 1712W17506 | C2: P1 | D2: Supervision | E2: Orange Money | F2: 43095.462 | G2: 04/01/2018 16:28 | H2: 13283 | I2: Instabilités sur Orange Money | J2: Saturation de la table de sessions TCP en cours(97-98%) sur le firewall Orange Infra ( PFSense) | K2: Augmentation de la capacité de la table de sessions TCP( de 47.000 à 201.000 sessions) et redémarrage du firewall | L2: GOS | M2: Clos | O2: =IF(AND(C2=Mai_2018!$B$47,H2<=Mai_2018!$D$47),"ISLA",IF((AND(C2=Mai_2018!$B$48,H2<=Mai_2018!$D$48)),"ISLA",IF((AND(C2=Mai_2018!$B$49,H2<=Mai_2018!$D$49)),"ISLA","OSLA"))) -> OSLA
A3: 2 | B3: 1801X31657 | C3: P1 | D3: Supervision | E3: E-recharge, Voix, Data mobile, SMS, USSD | F3: 43101.097 | G3: 43101.115 | H3: 25 | I3: Echecs de 60% des transactions E-recharge, consultation solde crédit et Data | J3: Redémarrage de plusieurs OCPRO sur le OCS6 | K3: Switching de l'OCS6 vers l'OCS5 | L3: GNOC | M3: Clos | O3: =IF(AND(C3=Mai_2018!$B$47,H3<=Mai_2018!$D$47),"ISLA",IF((AND(C3=Mai_2018!$B$48,H3<=Mai_2018!$D$48)),"ISLA",IF((AND(C3=Mai_2018!$B$49,H3<=Mai_2018!$D$49)),"ISLA","OSLA"))) -> ISLA
A4: 3 | B4: 1801X71667 | C4: P1 | D4: SSPO | E4: MyOrange / OBeta | F4: 43102.882 | G4: 43103.316 | H4: 625 | I4: MyOrange | J4: Crash du pare-feu physique | K4: Remplacement du pare-feu physique | L4: SSPO | M4: Clos | O4: =IF(AND(C4=Mai_2018!$B$47,H4<=Mai_2018!$D$47),"ISLA",IF((AND(C4=Mai_2018!$B$48,H4<=Mai_2018!$D$48)),"ISLA",IF((AND(C4=Mai_2018!$B$49,H4<=Mai_2018!$D$49)),"ISLA","OSLA"))) -> OSLA
A5: 4 | B5: 1801X71882 | C5: P1 | D5: SSPO | E5: AppsOrange | F5: 43102.882 | G5: 43103.358 | H5: 685 | I5: AppsOrange | J5: Crash du pare-feu physique | K5: Remplacement du pare-feu physique | L5: SSPO | M5: Clos | O5: =IF(AND(C5=Mai_2018!$B$47,H5<=Mai_2018!$D$47),"ISLA",IF((AND(C5=Mai_2018!$B$48,H5<=Mai_2018!$D$48)),"ISLA",IF((AND(C5=Mai_2018!$B$49,H5<=Mai_2018!$D$49)),"ISLA","OSLA"))) -> OSLA
A6: 5 | B6: 1801X71866 | C6: P2 | D6: SSPO | E6: Orange Money add-on / Web Payment | F6: 43102.868 | G6: 43103.31 | H6: 637 | I6: Orange Money add-on / Web Payment | J6: Crash du pare-feu physique | K6: Remplacement du pare-feu physique | L6: SSPO | M6: Clos | O6: =IF(AND(C6=Mai_2018!$B$47,H6<=Mai_2018!$D$47),"ISLA",IF((AND(C6=Mai_2018!$B$48,H6<=Mai_2018!$D$48)),"ISLA",IF((AND(C6=Mai_2018!$B$49,H6<=Mai_2018!$D$49)),"ISLA","OSLA"))) -> OSLA
A7: 6 | B7: 1801Y04958 | C7: P1 | D7: SSPO | E7: Orange Money add-on / Bank to Wallet / Ecobank | F7: 43103.785 | G7: 43103.826 | H7: 60 | I7: Impossible de faire des transactions bancaire via OM | J7: Perte de connexion avec le partenaire Ecobank | K7: Retablissement de la connexion | L7: SSPO | M7: Clos | O7: =IF(AND(C7=Mai_2018!$B$47,H7<=Mai_2018!$D$47),"ISLA",IF((AND(C7=Mai_2018!$B$48,H7<=Mai_2018!$D$48)),"ISLA",IF((AND(C7=Mai_2018!$B$49,H7<=Mai_2018!$D$49)),"ISLA","OSLA"))) -> ISLA
A8: 7 | B8: 1801Y34694 | C8: P1 | D8: Supervision | E8: Mobile TV | F8: 43104.64 | G8: 43104.669 | H8: 42 | I8: Indisponibilité des chaines West-Africa, Boom TV, 2STV, RTG | J8: le dongle satellite était down | K8: Reset du dongle | L8: OLS | M8: Clos | O8: =IF(AND(C8=Mai_2018!$B$47,H8<=Mai_2018!$D$47),"ISLA",IF((AND(C8=Mai_2018!$B$48,H8<=Mai_2018!$D$48)),"ISLA",IF((AND(C8=Mai_2018!$B$49,H8<=Mai_2018!$D$49)),"ISLA","OSLA"))) -> ISLA
A9: 8 | B9: 1801Z31688 | C9: P1 | D9: SSPO | E9: Orange Money add-on / Bank to Wallet / Ecobank | F9: 43108.796 | G9: 43108.838 | H9: 60 | I9: Impossible de faire des transactions bancaire via OM | J9: Perte de connexion avec le partenaire Ecobank | K9: Retablissement de la connexion | L9: SSPO | M9: Clos | O9: =IF(AND(C9=Mai_2018!$B$47,H9<=Mai_2018!$D$47),"ISLA",IF((AND(C9=Mai_2018!$B$48,H9<=Mai_2018!$D$48)),"ISLA",IF((AND(C9=Mai_2018!$B$49,H9<=Mai_2018!$D$49)),"ISLA","OSLA"))) -> ISLA
A10: 9 | B10: 1801Z34552 | C10: P1 | D10: Supervision | E10: FFC | F10: 43109.014 | G10: 43109.4 | H10: 556 | I10: FootBall Fans CluB (*191#) | J10: Plantage du processus frontal USSD | K10: Redémarrage du processus frontal USSD | L10: ASPIDER | M10: Clos | O10: =IF(AND(C10=Mai_2018!$B$47,H10<=Mai_2018!$D$47),"ISLA",IF((AND(C10=Mai_2018!$B$48,H10<=Mai_2018!$D$48)),"ISLA",IF((AND(C10=Mai_2018!$B$49,H10<=Mai_2018!$D$49)),"ISLA","OSLA"))) -> OSLA
A11: 10 | B11: 1801Z70090 | C11: P1 | D11: SSPO | E11: MyOrange / Orange Beta | F11: 43110.301 | G11: 43110.369 | H11: 97 | I11: MyOrange | J11: indisponibilité du WT pour certaines des filiales due à des mauvaises configurations lors d'une opération | K11: Correction manuelle du problème de configuration du côté WT.COM | L11: SSPO | M11: Clos | O11: =IF(AND(C11=Mai_2018!$B$47,H11<=Mai_2018!$D$47),"ISLA",IF((AND(C11=Mai_2018!$B$48,H11<=Mai_2018!$D$48)),"ISLA",IF((AND(C11=Mai_2018!$B$49,H11<=Mai_2018!$D$49)),"ISLA","OSLA"))) -> ISLA
A12: 11 | B12: 1801Z71927 | C12: P1 | D12: SSPO | E12: Orange Money add-on / Bank to Wallet / Ecobank | F12: 43110.34 | G12: 43110.377 | H12: 53 | I12: Impossible de faire des transactions bancaire via OM | J12: Opération planifiée(impact non prévu) | K12: Roll back | L12: SSPO | M12: Clos | O12: =IF(AND(C12=Mai_2018!$B$47,H12<=Mai_2018!$D$47),"ISLA",IF((AND(C12=Mai_2018!$B$48,H12<=Mai_2018!$D$48)),"ISLA",IF((AND(C12=Mai_2018!$B$49,H12<=Mai_2018!$D$49)),"ISLA","OSLA"))) -> ISLA
A13: 12 | B13: 1801A10964 | C13: P1 | D13: SSPO | E13: Orange Money | F13: 43111.46 | G13: 43111.465 | H13: 6 | I13: Impossibilité d'effectuer des transactions pendant un intervalle d'environ 6 minutes | J13: Dû à un APT côté DIF (T801042519) | K13: aucune | L13: SSPO | M13: Clos | O13: =IF(AND(C13=Mai_2018!$B$47,H13<=Mai_2018!$D$47),"ISLA",IF((AND(C13=Mai_2018!$B$48,H13<=Mai_2018!$D$48)),"ISLA",IF((AND(C13=Mai_2018!$B$49,H13<=Mai_2018!$D$49)),"ISLA","OSLA"))) -> ISLA
A14: 13 | B14: 1801A25215 | C14: P1 | D14: Supervision | E14: Nomad | F14: 43111.625 | G14: 43111.763 | H14: 199 | I14: Indisponibilité à la page Nomad | J14: Saturation du répertoire /opt/application/nomadsubscription | K14: Purge du répertoire | L14: GOS | M14: Clos | O14: =IF(AND(C14=Mai_2018!$B$47,H14<=Mai_2018!$D$47),"ISLA",IF((AND(C14=Mai_2018!$B$48,H14<=Mai_2018!$D$48)),"ISLA",IF((AND(C14=Mai_2018!$B$49,H14<=Mai_2018!$D$49)),"ISLA","OSLA"))) -> OSLA
... A32: 31 | B32: 1801E68898 | C32: P1 | D32: Supervision | E32: Consultation de solde data (*222*5#) | F32: 43129.556 | G32: 43129.649 | H32: 135 | I32: Impossible de consulter le solde data avec *222*5*#. Service indisponible | J32: Bagotement réseau sur l'environnement virtuel de Sonfonia | K32: Aucune | L32: ASBD | M32: Clos | O32: =IF(AND(C32=Mai_2018!$B$47,H32<=Mai_2018!$D$47),"ISLA",IF((AND(C32=Mai_2018!$B$48,H32<=Mai_2018!$D$48)),"ISLA",IF((AND(C32=Mai_2018!$B$49,H32<=Mai_2018!$D$49)),"ISLA","OSLA"))) -> OSLA
B47: P1 | C47: 2h | D47: 120
B48: P2 | C48: 4h | D48: 240
B49: P3 | C49: 2jr | D49: =1440*2 -> 2880
B50: P4 | C50: 3jr | D50: =3*1440 -> 4320

Sheet Février_2018
A1: N° | B1: N°ticket | C1: Priorité | D1: Origine | E1: Nom Service | F1: Date & heure de début | G1: Date & heure de fin | H1: Durée (mn) | I1: Description | J1: Cause de l'incident | K1: Actions correctives | L1: TMC | M1: Statut | N1: Observation | O1: SLA
A2: 1 | B2: 1802F56763 | C2: P1 | D2: GOS | E2: Gameloft, Myorange, CMS, SMS_API, OTAP, MegaWin | F2: 43132.505 | G2: 43132.533 | H2: 40 | I2: instabilité/indisponibilité Gameloft, Myorange, CMS, SMS_API, OTAP, MegaWin | J2: Hausse de charge CPU a été observé sur la VM opsdpgosumscl02 | K2: Déplacement de la VM vers une autre LAME et redémarrage | L2: GOS | M2: Clos | O2: =IF(AND(C2=$B$47,H2<=$D$47),"ISLA",IF((AND(C2=$B$48,H2<=$D$48)),"ISLA",IF((AND(C2=$B$49,H2<=$D$49)),"ISLA","OSLA"))) -> ISLA
A3: 2 | B3: 1802F67855 | C3: P1 | D3: GNOC | E3: Roaming data | F3: 43132.726 | G3: 43133.427 | H3: 1010 | I3: Probable dysfonctionnement du service data Roaming | J3: Indisponibilité du Serveur eDNS de sonfonia | K3: Redémarrage du Serveur | L3: GNOC | M3: Clos | O3: =IF(AND(C3=$B$47,H3<=$D$47),"ISLA",IF((AND(C3=$B$48,H3<=$D$48)),"ISLA",IF((AND(C3=$B$49,H3<=$D$49)),"ISLA","OSLA"))) -> OSLA
A4: 3 | B4: 1802G21518 | C4: P2 | D4: Supervision | E4: Webtop | F4: 43135.911 | G4: 43136.017 | H4: 153 | I4: Indisponibilité de la page Webtop | J4: Débordement régulier du filesystem suite à l'augmentation du trafic et donc du volume journalier de log. | K4: Réduction en moitié la consommation de log en supprimant le logging du champ User-Agent | L4: GOS | M4: Clos | O4: =IF(AND(C4=$B$47,H4<=$D$47),"ISLA",IF((AND(C4=$B$48,H4<=$D$48)),"ISLA",IF((AND(C4=$B$49,H4<=$D$49)),"ISLA","OSLA"))) -> ISLA
A5: 4 | B5: 1802G53210 | C5: P1 | D5: SSPO | E5: Orange Money add-on / Bank to Wallet / Ecobank | F5: 43137.038 | G5: 43137.066 | H5: 40 | I5: Impossible d'effectuer des transactions bancaires via OM | J5: Perte de connexion avec le partenaire Ecobank | K5: Retablissement de la connexion | L5: SSPO | M5: Clos | O5: =IF(AND(C5=$B$47,H5<=$D$47),"ISLA",IF((AND(C5=$B$48,H5<=$D$48)),"ISLA",IF((AND(C5=$B$49,H5<=$D$49)),"ISLA","OSLA"))) -> ISLA
A6: 5 | B6: 1802G55044 | C6: P1 | D6: GOS | E6: Otap | F6: 43137.273 | G6: 43137.308 | H6: 51 | I6: Non détection de nouveaux abonnés et non envoie des settings | J6: Arrêt du serveur de transfert de fichier (Axway) | K6: Redemarage du serveur Axway | L6: GOS | M6: Clos | O6: =IF(AND(C6=$B$47,H6<=$D$47),"ISLA",IF((AND(C6=$B$48,H6<=$D$48)),"ISLA",IF((AND(C6=$B$49,H6<=$D$49)),"ISLA","OSLA"))) -> ISLA
A7: 6 | B7: 1802G59297 | C7: P2 | D7: GOS | E7: MyOrange, megawin, agrobusiness, facebook ussd, otap, gameloft, cms, smsapi | F7: 43137.378 | G7: 43137.654 | H7: 397 | I7: Dégradations des services au-dessus du SDP | J7: Instabilité sur la machine virtuelle(VM) du module ESB NUMERO 3 du SDP | K7: Migration de la VM ‘’opsdpgosesbcl03’’ d’un ESXi à un autre moins sollicité et changement du DataStore | L7: GOS | M7: Clos | O7: =IF(AND(C7=$B$47,H7<=$D$47),"ISLA",IF((AND(C7=$B$48,H7<=$D$48)),"ISLA",IF((AND(C7=$B$49,H7<=$D$49)),"ISLA","OSLA"))) -> OSLA
A8: 7 | B8: 1802G83087 | C8: P1 | D8: Supervision | E8: Facebook_USSD | F8: 43138.454 | G8: 43138.503 | H8: 70 | I8: Impossibilité pour les clients de souscrire au service | J8: Surcharge de capacité au niveau du gestionnaire de souscriptions | K8: Augmentation de la capacité du gestionnaire de souscriptions | L8: Myriad | M8: Clos | O8: =IF(AND(C8=$B$47,H8<=$D$47),"ISLA",IF((AND(C8=$B$48,H8<=$D$48)),"ISLA",IF((AND(C8=$B$49,H8<=$D$49)),"ISLA","OSLA"))) -> ISLA
A9: 8 | B9: 1802H38701 | C9: P1 | D9: SSPO | E9: Orange Money add-on / Bank to Wallet / Ecobank | F9: 43139.774 | G9: 43139.804 | H9: 44 | I9: Impossible d'effectuer des transactions bancaires via OM | J9: Perte de connexion avec le partenaire Ecobank | K9: Retablissement de la connexion | L9: SSPO | M9: Clos | O9: =IF(AND(C9=$B$47,H9<=$D$47),"ISLA",IF((AND(C9=$B$48,H9<=$D$48)),"ISLA",IF((AND(C9=$B$49,H9<=$D$49)),"ISLA","OSLA"))) -> ISLA
A10: 9 | B10: 1802H67539 | C10: P1 | D10: Supervision | E10: E-recharge | F10: 43140.85 | G10: 43140.936 | H10: 124 | I10: Echec élevé des transactions E-recharge/IN (20%) | J10: seuil de connexion petit par rapport à la demande | K10: Aucune action faite | L10: GNOC | M10: Clos | O10: =IF(AND(C10=$B$47,H10<=$D$47),"ISLA",IF((AND(C10=$B$48,H10<=$D$48)),"ISLA",IF((AND(C10=$B$49,H10<=$D$49)),"ISLA","OSLA"))) -> OSLA
A11: 10 | B11: 1802H67849 | C11: P1 | D11: Supervision | E11: Consultation de solde data (*222*5#) | F11: 43140.844 | G11: 43140.917 | H11: 105 | I11: Impossibilité de consulté son solde data via le code USSD *222*5# | J11: Plantage du serveur glassfish | K11: Redémarrage du Serveur | L11: ASBD | M11: Clos | O11: =IF(AND(C11=$B$47,H11<=$D$47),"ISLA",IF((AND(C11=$B$48,H11<=$D$48)),"ISLA",IF((AND(C11=$B$49,H11<=$D$49)),"ISLA","OSLA"))) -> ISLA
A12: 11 | B12: 1802I61948 | C12: P1 | D12: Supervision | E12: Orange Money | F12: 43145.476 | G12: 43145.479 | H12: 5 | I12: Indisponibilité de tous les services Orange Money | J12: Problème sur l’interface EJET du réseaux GIN | K12: Investigation en cours | L12: SSPO | M12: Clos | O12: =IF(AND(C12=$B$47,H12<=$D$47),"ISLA",IF((AND(C12=$B$48,H12<=$D$48)),"ISLA",IF((AND(C12=$B$49,H12<=$D$49)),"ISLA","OSLA"))) -> ISLA
A13: 12 | B13: 1802I71797 | C13: P1 | D13: Supervision | E13: OTAP | F13: 43145.69 | G13: 43145.869 | H13: 258 | I13: Impossible d’envoyer des messages de configuration aux abonnés | J13: Problème sur le server de file d’attente(les files d'attente n'étaient pas traitées avec succès) | K13: Redémarrages du serveur de file d’attente | L13: GOS | M13: Clos | O13: =IF(AND(C13=$B$47,H13<=$D$47),"ISLA",IF((AND(C13=$B$48,H13<=$D$48)),"ISLA",IF((AND(C13=$B$49,H13<=$D$49)),"ISLA","OSLA"))) -> OSLA
... A29: 28 | B29: --- | C29: P1 | D29: SONATEL | E29: Internet LAN, tango, right Q, simplissimo | F29: 43159.419 | G29: 43159.634 | H29: 310 | I29: Lenteur Instabilités sur toutes les applications passant par internet Perte de supervision par intermittence via les robots daset | J29: Perte d’un des proxy et l’autre est actuellement surchargé | K29: Restauration du proxy | L29: SONATEL | M29: Clos | O29: =IF(AND(C29=$B$47,H29<=$D$47),"ISLA",IF((AND(C29=$B$48,H29<=$D$48)),"ISLA",IF((AND(C29=$B$49,H29<=$D$49)),"ISLA","OSLA"))) -> OSLA
B47: P1 | C47: 2h | D47: 120
B48: P2 | C48: 4h | D48: 240
B49: P3 | C49: 2jr | D49: =1440*2 -> 2880
B50: P4 | C50: 3jr | D50: =3*1440 -> 4320

Sheet Mars_2018
A1: N° | B1: N°ticket | C1: Priorité | D1: Origine | E1: Nom Service | F1: Date & heure de début | G1: Date & heure de fin | H1: Durée (mn) | I1: Description | J1: Cause de l'incident | K1: Actions correctives | L1: TMC | M1: Statut | N1: Observation | O1: SLA
A2: 1 | B2: 1803M11844 | C2: P1 | D2: Supervision | E2: OTAP | F2: 43160.216 | G2: 43160.374 | H2: 227 | I2: indisponibilté OTAP, report avantage | J2: Plantage du RabbitMQ dû à une partition pleine sur le /var du serveur ADC | K2: Redémarrage du RabbitMQ | L2: GOS | M2: Clos | O2: =IF(AND(C2=$B$47,H2<=$D$47),"ISLA",IF((AND(C2=$B$48,H2<=$D$48)),"ISLA",IF((AND(C2=$B$49,H2<=$D$49)),"ISLA","OSLA"))) -> OSLA
A3: 2 | B3: 1803M17585 | C3: P2 | D3: Supervision | E3: Lenteur sur l'internet | F3: 43160.376 | G3: 43160.671 | H3: 424 | I3: Internet via le LAN, Tango, Right Q, KMC,Robot daset, Oceane, | J3: Perte d’un des proxy et l’autre est actuellement surchargé | K3: Restauration du proxy | L3: SONATEL | M3: Clos | O3: =IF(AND(C3=$B$47,H3<=$D$47),"ISLA",IF((AND(C3=$B$48,H3<=$D$48)),"ISLA",IF((AND(C3=$B$49,H3<=$D$49)),"ISLA","OSLA"))) -> OSLA
A4: 3 | B4: 1803M27052 | C4: P1 | D4: Supervision | E4: Kaabu | F4: 43160.576 | G4: 43161.379 | H4: 1156 | I4: inidsponibilité du service Kaabu | J4: Inconnue | K4: Aucune | L4: OML | M4: Clos | O4: =IF(AND(C4=$B$47,H4<=$D$47),"ISLA",IF((AND(C4=$B$48,H4<=$D$48)),"ISLA",IF((AND(C4=$B$49,H4<=$D$49)),"ISLA","OSLA"))) -> OSLA
A5: 4 | B5: 1803M37387 | C5: P1 | D5: SSPO | E5: Orange Money add-on / Bank to Wallet / Ecobank | F5: 43160.802 | G5: 43160.915 | H5: 162 | I5: Impossibilité d'effectuer des transactions bancaire via Orange Money | J5: Perte de connexion avec le partenaire Ecobank | K5: Rétablissement de la connexion | L5: SSPO | M5: Clos | O5: =IF(AND(C5=$B$47,H5<=$D$47),"ISLA",IF((AND(C5=$B$48,H5<=$D$48)),"ISLA",IF((AND(C5=$B$49,H5<=$D$49)),"ISLA","OSLA"))) -> OSLA
A6: 5 | B6: 1803M43264 | C6: P1 | D6: SSPO | E6: Orange Money add-on / Bank to Wallet / Ecobank | F6: 43161.306 | G6: 43161.357 | H6: 74 | I6: Impossibilité d'effectuer des transactions bancaire via Orange Money | J6: Perte de connexion avec le partenaire Ecobank | K6: retablissement de la connexion avec le partenaire ECOBANK | L6: SSPO | M6: Clos | O6: =IF(AND(C6=$B$47,H6<=$D$47),"ISLA",IF((AND(C6=$B$48,H6<=$D$48)),"ISLA",IF((AND(C6=$B$49,H6<=$D$49)),"ISLA","OSLA"))) -> ISLA
A7: 6 | B7: 1803M81364 | C7: P1 | D7: Supervision | E7: E-recharge | F7: 43162.674 | G7: 43162.778 | H7: 150 | I7: Echecs des transactions E-recharge | J7: Les sessions du pare-feu (Firewall) IN ZTE étaient surchargées, de sorte que les nouvelles attributions de sessions échouaient | K7: Redémarrage du firewall et suppression manuelle | L7: SSPO | M7: Clos | O7: =IF(AND(C7=$B$47,H7<=$D$47),"ISLA",IF((AND(C7=$B$48,H7<=$D$48)),"ISLA",IF((AND(C7=$B$49,H7<=$D$49)),"ISLA","OSLA"))) -> OSLA
A8: 7 | B8: 1803M81797 | C8: P1 | D8: Supervision | E8: Consultation de solde data (*222*5#) | F8: 43162.673 | G8: 43162.743 | H8: 101 | I8: Impossibilité de consulter le solde data via USSD (*222*5#) | J8: Plantage du serveur glassfish | K8: Redémarrage du serveur | L8: ASBD | M8: Clos | O8: =IF(AND(C8=$B$47,H8<=$D$47),"ISLA",IF((AND(C8=$B$48,H8<=$D$48)),"ISLA",IF((AND(C8=$B$49,H8<=$D$49)),"ISLA","OSLA"))) -> ISLA
A9: 8 | B9: 1803M82159 | C9: P2 | D9: SSPO | E9: MyOrange/Orange et Moi | F9: 43162.733 | G9: 43162.767 | H9: 49 | I9: Echec de 50% des opérations de consultation de solde via l'application | J9: meme cause que l'incident N°4. Les sessions du pare-feu (Firewall) IN ZTE étaient surchargées, de sorte que les nouvelles attributions de sessions échouaient | K9: Redémarrage du firewall et suppression manuelle | L9: SSPO | M9: Clos | O9: =IF(AND(C9=$B$47,H9<=$D$47),"ISLA",IF((AND(C9=$B$48,H9<=$D$48)),"ISLA",IF((AND(C9=$B$49,H9<=$D$49)),"ISLA","OSLA"))) -> ISLA
A10: 9 | B10: 1803M89735 | C10: P1 | D10: SSPO | E10: Orange Money add-on / canal + | F10: 43163.443 | G10: 43164.012 | H10: 820 | I10: Impossible de renouveler les abonnements canal + via OM | J10: congestion "table size" de la base de donnée | K10: extension "table size" de la base de donnée | L10: SSPO | M10: Clos | O10: =IF(AND(C10=$B$47,H10<=$D$47),"ISLA",IF((AND(C10=$B$48,H10<=$D$48)),"ISLA",IF((AND(C10=$B$49,H10<=$D$49)),"ISLA","OSLA"))) -> OSLA
A11: 10 | B11: 1803O13726 | C11: P1 | D11: Supervision | E11: CMS | F11: 43164.5 | G11: 43164.576 | H11: 109 | I11: Non réception du contenu après souscription (*111# ou 8036) au service | J11: Nombre de TPS configuré atteint ce qui a créé une file d’attente | K11: Aucune | L11: GOS | M11: Clos | O11: =IF(AND(C11=$B$47,H11<=$D$47),"ISLA",IF((AND(C11=$B$48,H11<=$D$48)),"ISLA",IF((AND(C11=$B$49,H11<=$D$49)),"ISLA","OSLA"))) -> ISLA
A12: 11 | B12: 1803N17551 | C12: P2 | D12: Supervision | E12: Nomad | F12: 43164.616 | G12: 43164.696 | H12: 115 | I12: Impossible de valider les contrats | J12: Remplissage de la partition /var du serveur d’application à 100%. | K12: Purge de la partition /var du serveur d’application | L12: GOS | M12: Clos | O12: =IF(AND(C12=$B$47,H12<=$D$47),"ISLA",IF((AND(C12=$B$48,H12<=$D$48)),"ISLA",IF((AND(C12=$B$49,H12<=$D$49)),"ISLA","OSLA"))) -> ISLA
A13: 12 | B13: 1803N23237 | C13: P1 | D13: SSPO | E13: Orange Money add-on / Bank to Wallet / Ecobank | F13: 43164.722 | G13: 43164.76 | H13: 55 | I13: Impossibilité d'effectuer des transactions bancaire via Orange Money | J13: Perte de connexion avec le partenaire Ecobank | K13: retablissement de la connexion avec le partenaire ECOBANK | L13: SSPO | M13: Clos | O13: =IF(AND(C13=$B$47,H13<=$D$47),"ISLA",IF((AND(C13=$B$48,H13<=$D$48)),"ISLA",IF((AND(C13=$B$49,H13<=$D$49)),"ISLA","OSLA"))) -> ISLA
... A41: 40 | B41: 1803T56563 | C41: P2 | D41: Supervision | E41: Data mobile | F41: 43190.84 | G41: 43190.882 | H41: 60 | I41: Baisse du trafic sur les deux STM16 de la Sonatel | J41: Inconnue | K41: Aucune | L41: GNOC | M41: Clos | O41: =IF(AND(C41=$B$47,H41<=$D$47),"ISLA",IF((AND(C41=$B$48,H41<=$D$48)),"ISLA",IF((AND(C41=$B$49,H41<=$D$49)),"ISLA","OSLA"))) -> ISLA
B47: P1 | C47: 2h | D47: 120
B48: P2 | C48: 4h | D48: 240
B49: P3 | C49: 2jr | D49: =1440*2 -> 2880
B50: P4 | C50: 3jr | D50: =3*1440 -> 4320

Sheet Avril_2018
A1: N° | B1: N°ticket | C1: Priorité | D1: Origine | E1: Nom Service | F1: Date & heure de début | G1: Date & heure de fin | H1: Durée (mn) | I1: Description | J1: Cause de l'incident | K1: Actions correctives | L1: TMC | M1: Statut | N1: Observation | O1: SLA
A2: 1 | B2: 1804U07005/1804U07552 | C2: P2 | D2: SSPO | E2: E-recharge | F2: 43193.86 | G2: 43193.924 | H2: 92 | I2: Echec des transactions E-recharge | J2: Problème de disque dur sur L'ocs5 | K2: Service rétabli sans action / Action éffectué après (Basculement du service sur OCS6 et redemarage de OCS5) | L2: GNOC | M2: Clos | O2: =IF(AND(C2=$B$47,H2<=$D$47),"ISLA",IF((AND(C2=$B$48,H2<=$D$48)),"ISLA",IF((AND(C2=$B$49,H2<=$D$49)),"ISLA","OSLA"))) -> ISLA
A3: 2 | B3: 1804U28648 | C3: P1 | D3: SSPO | E3: Orange Money add-on / Bank to Wallet / Ecobank | F3: 43194.574 | G3: 43194.614 | H3: 58 | I3: Impossible d’effectuer des transactions bancaires via OM | J3: Perte de connexion avec le partenaire Ecobank | K3: Rétablissement de la connexion avec le partenaire | L3: SSPO | M3: Clos | O3: =IF(AND(C3=$B$47,H3<=$D$47),"ISLA",IF((AND(C3=$B$48,H3<=$D$48)),"ISLA",IF((AND(C3=$B$49,H3<=$D$49)),"ISLA","OSLA"))) -> ISLA
A4: 3 | B4: 1804U37282 | C4: P3 | D4: Supervision | E4: Orange Money | F4: 43194.823 | G4: 43194.938 | H4: 165 | I4: Instabilités des services | J4: Echecs des requetes push USSD avec le code HTTP 408 | K4: Aucune | L4: GNOC | M4: Clos | O4: =IF(AND(C4=$B$47,H4<=$D$47),"ISLA",IF((AND(C4=$B$48,H4<=$D$48)),"ISLA",IF((AND(C4=$B$49,H4<=$D$49)),"ISLA","OSLA"))) -> ISLA
A5: 4 | B5: 1804U55095 | C5: P1 | D5: Supervision | E5: Facebook_USSD | F5: 43195.501 | G5: 43195.536 | H5: 51 | I5: Impossible d’accéder au menu *444# | J5: Probleme de connectivité entre le MS et les Cellgate de Myriad | K5: Aucune | L5: Myriad | M5: Clos | O5: =IF(AND(C5=$B$47,H5<=$D$47),"ISLA",IF((AND(C5=$B$48,H5<=$D$48)),"ISLA",IF((AND(C5=$B$49,H5<=$D$49)),"ISLA","OSLA"))) -> ISLA
A6: 5 | B6: 1804U63093 | C6: P1 | D6: Supervision | E6: Orange Money | F6: 43195.67 | G6: 43195.701 | H6: 45 | I6: Indisponibilité Orange Money | J6: Indisponibilité Orange infa ( les actions de troubleshooting (redemarrage du firewall) ont impactées OM) / Suppression de ports 1-2 et 9-10 dans la mise à jour du vlan 1100 dans le cadre des configurations des nouvelles lames qui est chargé du management du HA | K6: Service rétabli après redemarrage du FW / Action éffectué après (Correction du vlan 1100 avec ajout des ports 1-2 , 5-10 et 15-16) | L6: ASBD/GOS | M6: Clos | O6: =IF(AND(C6=$B$47,H6<=$D$47),"ISLA",IF((AND(C6=$B$48,H6<=$D$48)),"ISLA",IF((AND(C6=$B$49,H6<=$D$49)),"ISLA","OSLA"))) -> ISLA
A7: 6 | B7: 1804U97805 | C7: P2 | D7: SSPO | E7: E-recharge | F7: 43197.333 | G7: 43197.481 | H7: 212 | I7: Echec des rechargements via OM (Achat de credit) | J7: Non rechargement du compte tango | K7: Rechargement du compte tango | L7: OGN | M7: Clos | O7: =IF(AND(C7=$B$47,H7<=$D$47),"ISLA",IF((AND(C7=$B$48,H7<=$D$48)),"ISLA",IF((AND(C7=$B$49,H7<=$D$49)),"ISLA","OSLA"))) -> ISLA
A8: 7 | B8: 18004V33104 | C8: P1 | D8: Supervision | E8: SMS_API | F8: 43199.515 | G8: 43199.566 | H8: 73 | I8: Echec d’activation du service | J8: Inconnue | K8: Aucune | L8: GOS | M8: Clos | O8: =IF(AND(C8=$B$47,H8<=$D$47),"ISLA",IF((AND(C8=$B$48,H8<=$D$48)),"ISLA",IF((AND(C8=$B$49,H8<=$D$49)),"ISLA","OSLA"))) -> ISLA
A9: 8 | B9: 1804V44000 | C9: P1 | D9: Supervision | E9: Nomad | F9: 43199.729 | G9: 43200.615 | H9: 1275 | I9: Impossibilité d'importer des contrats et pieces d'identité | J9: Inconnue | K9: Aucune | L9: GOS | M9: Clos | O9: =IF(AND(C9=$B$47,H9<=$D$47),"ISLA",IF((AND(C9=$B$48,H9<=$D$48)),"ISLA",IF((AND(C9=$B$49,H9<=$D$49)),"ISLA","OSLA"))) -> OSLA
A10: 9 | B10: 1804V63292 | C10: P2 | D10: Supervision | E10: Orange Money | F10: 43200.508 | G10: 43200.511 | H10: 5 | I10: Indisponibilité Orange Money | J10: Problèmes de réseau entre les serveurs USSD et Revers Proxy | K10: Aucune | L10: SSPO | M10: Clos | O10: =IF(AND(C10=$B$47,H10<=$D$47),"ISLA",IF((AND(C10=$B$48,H10<=$D$48)),"ISLA",IF((AND(C10=$B$49,H10<=$D$49)),"ISLA","OSLA"))) -> ISLA
A11: 10 | B11: 1804W83161 | C11: P2 | D11: SONATEL | E11: Messagerie electronique | F11: 43200.417 | G11: 43200.458 | H11: 60 | I11: Lenteur sur la messagerie | J11: Une base exchange ne delivre pas convenablement les mails | K11: Synchronisation des bases | L11: SONATEL | M11: Clos | O11: =IF(AND(C11=$B$47,H11<=$D$47),"ISLA",IF((AND(C11=$B$48,H11<=$D$48)),"ISLA",IF((AND(C11=$B$49,H11<=$D$49)),"ISLA","OSLA"))) -> ISLA
A12: 11 | B12: 1804V77306 | C12: P1 | D12: SSPO | E12: Orange Money add-on / Bank to Wallet / Ecobank | F12: 43201.018 | G12: 43201.058 | H12: 58 | I12: Impossible d’effectuer des transactions bancaires via OM | J12: Perte de connexion avec le partenaire Ecobank | K12: Rétablissement de la connexion avec le partenaire | L12: SSPO | M12: Clos | O12: =IF(AND(C12=$B$47,H12<=$D$47),"ISLA",IF((AND(C12=$B$48,H12<=$D$48)),"ISLA",IF((AND(C12=$B$49,H12<=$D$49)),"ISLA","OSLA"))) -> ISLA
